Workbook
Name SumUDig: '[1]1.Técnicas'!$E$32
Name SumUDig: InformeObservaciones!#REF!
Name SumUDig: Inicio!$E$29

Sheet Inicio
E1: v.20250827
B2: UECIJG / Dibujo asistido por computador - DAPC / Proyecto CAD
B3: Inicio / Grupos, integrantes y resúmen de calificaciones
B4: El proyecto se desarrolla en grupo, el número de estudiantes se indica al inicio del curso. Cada grupo tendrá un código numérico consecutivo asignado por el instructor. Los estudiantes deberán definir el nombre de su grupo de proyecto y crear un logotipo en AutoCAD. El código, logotipo y nombre del grupo deberán incluirse en todos los planos generados.
B7: Código del grupo
B8: 1
B9: Nombre del grupo
B10: ElectraLine
B12: Repositorio de archivos*
B13: https://shorturl.at/8lPad
B15: *La localización del repositorio se debe mantener activa durante todo el curso.
G16: Calificación proyecto
B17: Integrantes del grupo | G17: 0.3 | H17: 0.7
B18: # | C18: Nombre alumno | D18: Código alumno | E18: UDig | G18: Proyecto | H18: Auto-calificación | I18: Calificación final
B19: 1 | C19: ALVARO JOSE OSPINA PINTO | D19: 1000108883 | E19: =IFERROR(RIGHT(D19,1)*1,0) -> 3 | G19: =$E$39 -> 4.927619 | H19: 4 | I19: =G19*$G$17+H19*$H$17 -> 4.2782857
B20: 2 | C20: DARIA PAULA LORENA MARIN GUTIERREZ | D20: 1000105775 | E20: =IFERROR(RIGHT(D20,1)*1,0) -> 5 | G20: =$E$39 -> 4.927619 | H20: 5 | I20: =G20*$G$17+H20*$H$17 -> 4.9782857
B21: 3 | C21: JUAN ESTEBAN BAHAMON MONJE | D21: 1000109428 | E21: =IFERROR(RIGHT(D21,1)*1,0) -> 8 | G21: =$E$39 -> 4.927619 | H21: 4.5 | I21: =G21*$G$17+H21*$H$17 -> 4.6282857
B22: 4 | C22: JUANITA CARLOS PRIETO (A) | D22: 1000105722 | E22: =IFERROR(RIGHT(D22,1)*1,0) -> 2 | G22: =$E$39 -> 4.927619 | H22: 5 | I22: =G22*$G$17+H22*$H$17 -> 4.9782857
B23: 5 | C23: KAREN SOFIA VIVAS CARDENAS | D23: 1000108881 | E23: =IFERROR(RIGHT(D23,1)*1,0) -> 1 | G23: =$E$39 -> 4.927619 | H23: 4.5 | I23: =G23*$G$17+H23*$H$17 -> 4.6282857
B24: 6 | C24: OSCAR EDUARDO PEÑA CASTRO | D24: 1000104677 | E24: =IFERROR(RIGHT(D24,1)*1,0) -> 7 | G24: =$E$39 -> 4.927619 | H24: 5 | I24: =G24*$G$17+H24*$H$17 -> 4.9782857
B25: 7 | E25: =IFERROR(RIGHT(D25,1)*1,0) -> 0 | G25: =$E$39 -> 4.927619 | I25: =G25*$G$17+H25*$H$17 -> 1.4782857
B26: 8 | E26: =IFERROR(RIGHT(D26,1)*1,0) -> 0 | G26: =$E$39 -> 4.927619 | I26: =G26*$G$17+H26*$H$17 -> 1.4782857
B27: 9 | E27: =IFERROR(RIGHT(D27,1)*1,0) -> 0 | G27: =$E$39 -> 4.927619 | I27: =G27*$G$17+H27*$H$17 -> 1.4782857
B28: 10 | E28: =IFERROR(RIGHT(D28,1)*1,0) -> 0 | G28: =$E$39 -> 4.927619 | I28: =G28*$G$17+H28*$H$17 -> 1.4782857
D29: ∑UDig: | E29: =SUM(E19:E28) -> 26
B31: Resumen de calificaciones del proyecto
B32: # | C32: Especificación | E32: Calificación
B33: 1 | C33: Técnica | E33: =IF('1.Tecnica'!I19>0,'1.Tecnica'!I19,"") -> 5
B34: 2 | C34: Arquitectónica y estructural | E34: =IF('2.ArquitectonicaEstructural'!I95>0,'2.ArquitectonicaEstructural'!I95,"") -> 4.84
B35: 3 | C35: Eléctrica | E35: =IF('3.Electrica'!I28>0,'3.Electrica'!I28,"") -> 4.9642857
B36: 4 | C36: Bodegaje | E36: =IF('4.Bodegaje'!I23>0,'4.Bodegaje'!I23,"") -> 5
B37: 4 | C37: Planos | E37: =IF('5.Planos'!I17>0,'5.Planos'!I17,"") -> 5
B38: 5 | C38: Archivos | E38: =IF('6.Archivos'!H18>0,'6.Archivos'!H18,"") -> 4.7614286
D39: Promedio: | E39: =AVERAGE(E33:E38) -> 4.927619

Sheet InformeObservaciones
B2: UECIJG / Dibujo asistido por computador - DAPC / Proyecto CAD
B3: Observaciones generales de revisión de avance de proyecto
B4: Actualice los entregables de su proyecto de acuerdo a las siguientes observaciones e indicaciones realizadas por actividad.
B5: Código | C5: Actividad | D5: Informe | E5: Dedicación (hr) | F5: Observaciones CAD
B6: M01A01 | C6: 1.1. Conceptos básicos de diseño asistido por computador - CAD | D6: En la carpeta /report no se deben guardar tablas, éstas se almacenan en la carpeta /table. Para cada actividad se debe presentar un informe técnico independiente. Informe M01A01 no presentado. Incluir capturas de pantalla de los elementos dibujados en CAD correspondientes al avance de cada actividad. Los informes deben utilizar la plantilla de Microsoft Word suministrada. Informe sin conversión a Adobe Acrobat .pdf. | E6: 16 | F6: El nombre del archivo de proyecto se debe denominar DAPC.dwg (guardar el archivo DAPC M01A02.dwg con este nombre). Ver hoja 2.ArquitectonicaEstructural.
B7: M01A02a | C7: 1.2.a. Elementos básicos de dibujo / Creación de capas o layers | D7: Informe M01A02a incompleto, es necesario incluir tabla de contenido y demás elementos indicados en la plantilla. El archivo DAPC_AIALayerName.xlsx debe mantener su nombre original y se almacena en /table. El informe no han indicado que criterios utilizaron para definir los colores y grosores de las layers. | E7: 5.18 | F7: El nombre del archivo de proyecto se debe denominar DAPC.dwg (guardar el archivo DAPC M01A02.dwg con este nombre). Ver hoja 2.ArquitectonicaEstructural.
B8: M01A02b | C8: 1.2.b. Elementos básicos de dibujo / UCS y Geometrías | D8: En la carpeta /report no se deben guardar tablas, éstas se almacenan en la carpeta /table. Para cada actividad se debe presentar un informe técnico independiente. Informe M01A02b no presentado. Incluir capturas de pantalla de los elementos dibujados en CAD correspondientes al avance de cada actividad. Los informes deben utilizar la plantilla de Microsoft Word suministrada. | E8: 16 | F8: El nombre del archivo de proyecto se debe denominar DAPC.dwg (guardar el archivo DAPC M01A02.dwg con este nombre). Ver hoja 2.ArquitectonicaEstructural.
B9: M01A02c | C9: 1.2.c. Elementos básicos de dibujo / Curvas especiales
B10: M01A02d | C10: 1.2.d. Dibujo en 3D | D10: Informe sin investigación de qué es y para que sirve un pararrayos. Sin tabla con horas de dedicación.
B11: M01A03 | C11: 1.3. Bloques - Achurados- Viewports
B12: M01A04 | C12: 1.4. Textos, anotaciones y dimensionamiento | H12: Tercio 2
B13: M01A05 | C13: 1.5. Layout e Impresión | D13: Los diferentes layouts para la impresión de cada planao debían ser incorporados en el dibujo principal usando ViewPorts y no en archivos independientes. | H13: Tercio 2
B14: M01A06 | C14: 1.6. Proyecto de dibujo asistido por computadora con Autodesk AutoCAD | H14: Tercio 2
D16: Total: | E16: =SUM(E6:E15) -> 37.18
B17: Realizar los ajustes indicados en las observaciones para actualización de la calificación de avance del proyecto.

Sheet 0.Ejercicios
B2: UECIJG / Dibujo asistido por computador - DAPC
B3: 0. Ejercicios entregables a desarrollar
B4: Durante el desarrollo del curso, los grupos de proyecto presentarán los siguientes ejercicios siguiendo las especificaciones y parámetros definidos en cada actividad. Los dibujos de AutoCAD se almacenan en la carpeta /file/cad usando el nombre del ejercicio y la extensión .dwg.
B6: Ejercicio | C6: Descripción | D6: Figura | E6: Actividad | G6: Revisión | H6: Calificación
B7: 1.1. Conceptos básicos de diseño asistido por computador - CAD (para la calificación de los ejercicios, el nodo de inicio o punto de origen (X,Y) de coordenadas absolutas de todas las figuras, corresponde a la sumatoria del último dígito de los códigos de alumno de su grupo.)
A9: 1 | B9: M01A01E01 | C9: Aplicando los conceptos aprendidos de coordenadas absolutas y relativas, dibuje manualmente la siguiente figura asimétrica. El nodo de inicio deberá corresponder con la esquina superior más a la izquierda donde se encuentra el tramo de 15 metros. | D9: =_xlfn.IMAGE(_xlfn.CONCAT("https://github.com/rcfdtools/R.DAPC/blob/main/activity/",E9,"/graph/",B9,".jpg?raw=true")) -> #VALUE! | E9: M01A01 | F9: =HYPERLINK(_xlfn.CONCAT("https://github.com/rcfdtools/R.DAPC/blob/main/activity/",E9,"/Readme.md#ejercicio-",B9),"Ver") -> Ver | G9: Ajustar punto de origen a 26,26 | H9: 5
A10: 2 | B10: M01A01E02A | C10: Parte A: aplicando los conceptos aprendidos, cree secuencias de comandos (una con posiciones absolutas, otra con posiciones relativas y una final con ángulos) para la construcción de la figura presentada en el Ejercicio M01A00E01. Guarde la secuencia en _/file/report/M01A01E02A.txt. El nodo de inicio deberá corresponder con la esquina superior más a la izquierda donde se encuentra el tramo de 15 metros. | D10: =_xlfn.IMAGE(_xlfn.CONCAT("https://github.com/rcfdtools/R.DAPC/blob/main/activity/",E10,"/graph/",B10,".jpg?raw=true")) -> #VALUE! | E10: M01A01 | F10: =HYPERLINK(_xlfn.CONCAT("https://github.com/rcfdtools/R.DAPC/blob/main/activity/",E10,"/Readme.md#ejercicio-",B10),"Ver") -> Ver | G10: Secuencias correctas | H10: 5
A11: 3 | B11: M01A01E02B | C11: Parte B: utilizando secuencias de comandos, cree los siguientes elementos: 1. Triángulo rectángulo de 50 metros de base por 20 metros de alto con orígen en la coordenada absoluta indicada, 2. Triángulo equilátero de 50 metros de lado con orígen en la coordenada absoluta indicada, 3. Triángulo rectángulo con área de 200 m² y con orígen en la coordenada absoluta indicada. | E11: M01A01 | F11: =HYPERLINK(_xlfn.CONCAT("https://github.com/rcfdtools/R.DAPC/blob/main/activity/",E11,"/Readme.md#ejercicio-",B11),"Ver") -> Ver | G11: Secuencias correctas | H11: 5
A12: 4 | B12: M01A01E03a | C12: Para practicar las herramientas de dibujo asistido, construiremos en clase el siguiente dibujo isométrico a partir de líneas, dibujaremos las vistas proyectadas y vistas planas lateral derecha, superior, frontal y posterior, calcularemos las áreas de cada cara proyectada y el volúmen total del sólido. El origen de la figura está localizado en la esquina inferior del dibujo isométrico. | D12: =_xlfn.IMAGE(_xlfn.CONCAT("https://github.com/rcfdtools/R.DAPC/blob/main/activity/",E12,"/graph/",B12,".jpg?raw=true")) -> #VALUE! | E12: M01A01 | F12: =HYPERLINK(_xlfn.CONCAT("https://github.com/rcfdtools/R.DAPC/blob/main/activity/",E12,"/Readme.md#ejercicio-",B12),"Ver") -> Ver | G12: Volumen correcto 880000. | H12: 5
A13: 5 | B13: M01A01E04 | C13: Dibuje el siguiente dibujo isométrico a partir de líneas y dibuje las vistas proyectadas y planas lateral derecha, superior, frontal y posterior, calcule las áreas de cada cara proyectada y el volúmen total del sólido. El origen de la figura está localizado en la esquina inferior del dibujo isométrico. | D13: =_xlfn.IMAGE(_xlfn.CONCAT("https://github.com/rcfdtools/R.DAPC/blob/main/activity/",E13,"/graph/",B13,".jpg?raw=true")) -> #VALUE! | E13: M01A01 | F13: =HYPERLINK(_xlfn.CONCAT("https://github.com/rcfdtools/R.DAPC/blob/main/activity/",E13,"/Readme.md#ejercicio-",B13),"Ver") -> Ver | G13: Volumen correcto 184000. | H13: 5
A14: 6 | B14: M01A01E05 | C14: Dibuje el siguiente dibujo isométrico a partir de líneas y dibuje las vistas proyectadas y planas lateral derecha, superior, frontal y posterior, calcule las áreas de cada cara proyectada y el volúmen total del sólido. El origen de la figura está localizado en la esquina inferior del dibujo isométrico. | D14: =_xlfn.IMAGE(_xlfn.CONCAT("https://github.com/rcfdtools/R.DAPC/blob/main/activity/",E14,"/graph/",B14,".jpg?raw=true")) -> #VALUE! | E14: M01A01 | F14: =HYPERLINK(_xlfn.CONCAT("https://github.com/rcfdtools/R.DAPC/blob/main/activity/",E14,"/Readme.md#ejercicio-",B14),"Ver") -> Ver | G14: Volumen correcto 215000. | H14: 5
A15: 7 | B15: M01A01E06 | C15: Dibuje el siguiente dibujo isométrico a partir de líneas y dibuje las vistas proyectadas y planas lateral derecha, superior, frontal y posterior, calcule las áreas de cada cara proyectada y el volúmen total del sólido. El origen de la figura está localizado en la esquina inferior del dibujo isométrico. | D15: =_xlfn.IMAGE(_xlfn.CONCAT("https://github.com/rcfdtools/R.DAPC/blob/main/activity/",E15,"/graph/",B15,".jpg?raw=true")) -> #VALUE! | E15: M01A01 | F15: =HYPERLINK(_xlfn.CONCAT("https://github.com/rcfdtools/R.DAPC/blob/main/activity/",E15,"/Readme.md#ejercicio-",B15),"Ver") -> Ver | G15: Volumen correcto 414000. | H15: 5
A16: 8 | B16: M01A01E07 | C16: Dibuje el siguiente dibujo isométrico de una escalera a partir de líneas y dibuje las vistas proyectadas y planas lateral derecha, superior, frontal y posterior. El espesor del material de la escalera es 2.5. El origen de la figura está localizado en la esquina inferior izquierda del dibujo isométrico. | D16: =_xlfn.IMAGE(_xlfn.CONCAT("https://github.com/rcfdtools/R.DAPC/blob/main/activity/",E16,"/graph/",B16,".jpg?raw=true")) -> #VALUE! | E16: M01A01 | F16: =HYPERLINK(_xlfn.CONCAT("https://github.com/rcfdtools/R.DAPC/blob/main/activity/",E16,"/Readme.md#ejercicio-",B16),"Ver") -> Ver | G16: Sin volumen calculado. Es 9600. | H16: 4.5
B18: 1.2.a. Elementos básicos de dibujo / Creación de capas o layers
A19: 9 | B19: M01A02aE01 | C19: En el archivo M01A01a.dwg, cree las capas establecidas en el catálogo DAPC_AIALayerName.xlsx para el curso DACP. En las descripciones incluya el nombre de la disciplina un guion y la descripción, p. ej., Arquitectura - Área | E19: M01A02a | F19: =HYPERLINK(_xlfn.CONCAT("https://github.com/rcfdtools/R.DAPC/blob/main/activity/",E19,"/Readme.md#ejercicio-",B19),"Ver") -> Ver | H19: 5
B21: 1.2.b. Elementos básicos de dibujo / UCS y Geometrías (para la calificación de los ejercicios, el nodo de inicio o el punto de origen (X,Y) de coordenadas absolutas de todas las figuras, corresponde a la sumatoria del último dígito de los códigos de alumno de su grupo)
A23: 10 | B23: M01A02bE01 | C23: Para practicar las herramientas vistas en esta actividad, construiremos en clase el siguiente dibujo isométrico a partir de líneas, círculos y arcos, inscrita en una circunferencia de radio 10 metros. El origen de la figura está localizado en el centroide del círculo principal o en el cruce de los ejes principales. | D23: =_xlfn.IMAGE(_xlfn.CONCAT("https://github.com/rcfdtools/R.DAPC/blob/main/activity/",E23,"/graph/",B23,".jpg?raw=true")) -> #VALUE! | E23: M01A02b | F23: =HYPERLINK(_xlfn.CONCAT("https://github.com/rcfdtools/R.DAPC/blob/main/activity/",E23,"/Readme.md#ejercicio-",B23),"Ver") -> Ver | H23: 5
A24: 11 | B24: M01A02bE02 | C24: Dibuje la llave de tuercas presentada en la ilustración. El origen de la figura está localizado en el centroide del círculo principal o en el cruce de los ejes principales. | D24: =_xlfn.IMAGE(_xlfn.CONCAT("https://github.com/rcfdtools/R.DAPC/blob/main/activity/",E24,"/graph/",B24,".jpg?raw=true")) -> #VALUE! | E24: M01A02b | F24: =HYPERLINK(_xlfn.CONCAT("https://github.com/rcfdtools/R.DAPC/blob/main/activity/",E24,"/Readme.md#ejercicio-",B24),"Ver") -> Ver | H24: 5
A25: 12 | B25: M01A02bE03 | C25: Dibuje las siguientes formas geométricas con simetría axial mostradas en la ilustración, utilice las dimensiones mostradas en cada figura. El origen de la figura está localizado en el centroide del círculo principal o en el cruce de los ejes principales. | D25: =_xlfn.IMAGE(_xlfn.CONCAT("https://github.com/rcfdtools/R.DAPC/blob/main/activity/",E25,"/graph/",B25,".jpg?raw=true")) -> #VALUE! | E25: M01A02b | F25: =HYPERLINK(_xlfn.CONCAT("https://github.com/rcfdtools/R.DAPC/blob/main/activity/",E25,"/Readme.md#ejercicio-",B25),"Ver") -> Ver | H25: 5
A26: 13 | B26: M01A02bE04 | C26: Dibuje el siguiente elemento isométrico correspondiente a la cabeza de un martillo. El origen de la figura está localizado en la esquina inferior izquierda del dibujo isométrico. | D26: =_xlfn.IMAGE(_xlfn.CONCAT("https://github.com/rcfdtools/R.DAPC/blob/main/activity/",E26,"/graph/",B26,".jpg?raw=true")) -> #VALUE! | E26: M01A02b | F26: =HYPERLINK(_xlfn.CONCAT("https://github.com/rcfdtools/R.DAPC/blob/main/activity/",E26,"/Readme.md#ejercicio-",B26),"Ver") -> Ver | H26: 5
A27: 14 | B27: M01A02bE05 | C27: Dibuje el siguiente elemento isométrico correspondiente a un contra pasador. El origen de la figura está localizado en la esquina inferior izquierda del dibujo isométrico. | D27: =_xlfn.IMAGE(_xlfn.CONCAT("https://github.com/rcfdtools/R.DAPC/blob/main/activity/",E27,"/graph/",B27,".jpg?raw=true")) -> #VALUE! | E27: M01A02b | F27: =HYPERLINK(_xlfn.CONCAT("https://github.com/rcfdtools/R.DAPC/blob/main/activity/",E27,"/Readme.md#ejercicio-",B27),"Ver") -> Ver | H27: 5
A28: 15 | B28: M01A02bE06 | C28: Dibuje el siguiente elemento isométrico correspondiente a un tabique o ladrillo con perforaciones, en la cara frontal utilice la herramienta Mirror. El origen de la figura está localizado en la esquina inferior izquierda del dibujo isométrico. | D28: =_xlfn.IMAGE(_xlfn.CONCAT("https://github.com/rcfdtools/R.DAPC/blob/main/activity/",E28,"/graph/",B28,".jpg?raw=true")) -> #VALUE! | E28: M01A02b | F28: =HYPERLINK(_xlfn.CONCAT("https://github.com/rcfdtools/R.DAPC/blob/main/activity/",E28,"/Readme.md#ejercicio-",B28),"Ver") -> Ver | H28: 5
A29: 16 | B29: M01A02bE07 | C29: Dibuje el siguiente elemento isométrico correspondiente a pieza mecánica con perforaciones. El origen de la figura está localizado en el centroide del círculo principal o en el cruce de los ejes principales. | D29: =_xlfn.IMAGE(_xlfn.CONCAT("https://github.com/rcfdtools/R.DAPC/blob/main/activity/",E29,"/graph/",B29,".jpg?raw=true")) -> #VALUE! | E29: M01A02b | F29: =HYPERLINK(_xlfn.CONCAT("https://github.com/rcfdtools/R.DAPC/blob/main/activity/",E29,"/Readme.md#ejercicio-",B29),"Ver") -> Ver | H29: 5
A30: 17 | B30: M01A02bE08 | C30: Dibuje el siguiente elemento isométrico correspondiente a pieza mecánica con perforaciones. El origen de la figura está localizado en el centroide del círculo principal o en el cruce de los ejes principales. | D30: =_xlfn.IMAGE(_xlfn.CONCAT("https://github.com/rcfdtools/R.DAPC/blob/main/activity/",E30,"/graph/",B30,".jpg?raw=true")) -> #VALUE! | E30: M01A02b | F30: =HYPERLINK(_xlfn.CONCAT("https://github.com/rcfdtools/R.DAPC/blob/main/activity/",E30,"/Readme.md#ejercicio-",B30),"Ver") -> Ver | H30: 5
A31: 18 | B31: M01A02bE09 | C31: Creando un array de 10 líneas horizontales por 10 líneas verticales y trazando líneas, cree el logo de la UECIJG. El ancho y alto de la figura debe corresponder a la sumatoria del último dígito de los códigos de alumno de su grupo. El origen de la figura está localizado en la esquina inferior izquierda. | D31: =_xlfn.IMAGE(_xlfn.CONCAT("https://github.com/rcfdtools/R.DAPC/blob/main/activity/",E31,"/graph/",B31,".jpg?raw=true")) -> #VALUE! | E31: M01A02b | F31: =HYPERLINK(_xlfn.CONCAT("https://github.com/rcfdtools/R.DAPC/blob/main/activity/",E31,"/Readme.md#ejercicio-",B31),"Ver") -> Ver | H31: 5
B33: 1.2.c. Elementos básicos de dibujo / Curvas especiales (la elección de las coordenadas del centroide X,Y de cada figura es libre)
A34: 19 | B34: M01A02cE00 | C34: A partir de la longitud de los semiejes, generar las coordenadas de localización en 100 puntos sobre la elipse, trazar la polilínea en AutoCAD y luego suavizarla. Utilizando los parámetros de cálculo, trace con la herramienta ELLIPSE, la elipse compuesta por arcos y compare su longitud con la trazada a partir de puntos. La longitud del semieje mayor o a, corresponden a la sumatoria del último dígito de los códigos de alumno de su grupo; la longitud del semieje menor o b, corresponde al 35% de la longitud del semieje mayor. | D34: =_xlfn.IMAGE(_xlfn.CONCAT("https://github.com/rcfdtools/R.DAPC/blob/main/activity/",E34,"/graph/",B34,".jpg?raw=true")) -> #VALUE! | E34: M01A02c | F34: =HYPERLINK(_xlfn.CONCAT("https://github.com/rcfdtools/R.DAPC/blob/main/activity/",E34,"/Readme.md#ejercicio-",B34),"Ver") -> Ver | H34: 5
A35: 20 | B35: M01A02cE01 | C35: Trace las líneas constructivas y dibuje óvalos en AutoCAD a partir de arcos circulares, conociendo: eje mayor, eje menor, los dos ejes. Para el dibujo de un óvalo dado el eje menor, utilice una longitud igual a la sumatoria del último dígito de los códigos de alumno de su grupo. Para el dibujo de un óvalo dado el eje mayor, utilice una longitud igual a dos veces la sumatoria del último dígito de los códigos de alumno de su grupo. Para el dibujo de un óvalo dado el eje mayor y el eje menor, utilice como mayor valor una longitud igual la sumatoria del último dígito de los códigos de alumno de su grupo y como valor menor una longitud de 5/8 con respecto al valor anterior. | D35: =_xlfn.IMAGE(_xlfn.CONCAT("https://github.com/rcfdtools/R.DAPC/blob/main/activity/",E35,"/graph/",B35,".jpg?raw=true")) -> #VALUE! | E35: M01A02c | F35: =HYPERLINK(_xlfn.CONCAT("https://github.com/rcfdtools/R.DAPC/blob/main/activity/",E35,"/Readme.md#ejercicio-",B35),"Ver") -> Ver | G35: Faltaron dos de los óvalos. Ovalo a partir de 2 ejes con arcos superior e inferior incorrecto. | H35: 1.5
A36: 21 | B36: M01A02cE02 | C36: Trace las líneas constructivas y dibuje ovoides en AutoCAD a partir de arcos circulares, conociendo: eje mayor, eje menor, los dos ejes. Para el dibujo de un ovoide dado el eje menor, utilice una longitud igual a la sumatoria del último dígito de los códigos de alumno de su grupo. Para el dibujo de un ovoide dado el eje mayor, utilice una longitud igual a dos veces la sumatoria del último dígito de los códigos de alumno de su grupo. Para el dibujo de un ovoide dado el eje mayor y el eje menor, utilice como mayor valor una longitud igual la sumatoria del último dígito de los códigos de alumno de su grupo y como valor menor una longitud de 5/8 con respecto al valor anterior. | D36: =_xlfn.IMAGE(_xlfn.CONCAT("https://github.com/rcfdtools/R.DAPC/blob/main/activity/",E36,"/graph/",B36,".jpg?raw=true")) -> #VALUE! | E36: M01A02c | F36: =HYPERLINK(_xlfn.CONCAT("https://github.com/rcfdtools/R.DAPC/blob/main/activity/",E36,"/Readme.md#ejercicio-",B36),"Ver") -> Ver | G36: Ovoide a partir de dos ejes incorrecto, circulo inferior con radio incorrecto. | H36: 4
A37: 22 | B37: M01A02cE03A | C37: Parte A: utilizando los conceptos aprendidos acerca de óvalos, cree un libro formulado en Excel para el trazado de una superelipse, el tamaño y localización de la figura es de libre elección. | D37: =_xlfn.IMAGE(_xlfn.CONCAT("https://github.com/rcfdtools/R.DAPC/blob/main/activity/",E37,"/graph/",B37,".jpg?raw=true")) -> #VALUE! | E37: M01A02c | F37: =HYPERLINK(_xlfn.CONCAT("https://github.com/rcfdtools/R.DAPC/blob/main/activity/",E37,"/Readme.md#ejercicio-",B37),"Ver") -> Ver | G37: En la carpeta /table no esta el libro de Excel. | H37: 4
A38: 23 | B38: M01A02cE03B | C38: Parte B: investigue la forma geométrica que tienen las pistas de atletismo y realice el trazado de su contorno interno en AutoCAD, luego y utilizando la herramienta OFFSET, trace 8 líneas paralelas externas que le permitirán obtener 8 carriles y calcule la longitud de sus ejes centrales. | E38: M01A02c | F38: =HYPERLINK(_xlfn.CONCAT("https://github.com/rcfdtools/R.DAPC/blob/main/activity/",E38,"/Readme.md#ejercicio-",B38),"Ver") -> Ver | H38: 5
A39: 24 | B39: M01A02cE04 | C39: Utilizando los conceptos aprendidos acerca de parábolas, trace una parábola cuya longitud horizontal corresponda a la sumatoria del último dígito de los códigos de alumno de su grupo y con longitud vertical correspondiente al 40% de la longitud horizontal. | D39: =_xlfn.IMAGE(_xlfn.CONCAT("https://github.com/rcfdtools/R.DAPC/blob/main/activity/",E39,"/graph/",B39,".jpg?raw=true")) -> #VALUE! | E39: M01A02c | F39: =HYPERLINK(_xlfn.CONCAT("https://github.com/rcfdtools/R.DAPC/blob/main/activity/",E39,"/Readme.md#ejercicio-",B39),"Ver") -> Ver | H39: 5
A40: 25 | B40: M01A02cE05 | C40: Utilizando los conceptos aprendidos de hipérbolas, trace una hipérbola cuya longitud horizontal o eje real corresponda a la sumatoria del último dígito de los códigos de alumno de su grupo y con longitud vertical o eje imaginario correspondiente 2.25 veces la longitud horizontal. | D40: =_xlfn.IMAGE(_xlfn.CONCAT("https://github.com/rcfdtools/R.DAPC/blob/main/activity/",E40,"/graph/",B40,".jpg?raw=true")) -> #VALUE! | E40: M01A02c | F40: =HYPERLINK(_xlfn.CONCAT("https://github.com/rcfdtools/R.DAPC/blob/main/activity/",E40,"/Readme.md#ejercicio-",B40),"Ver") -> Ver | G40: Sin líneas constructivas, sin fraccionamiento de eje de referencia, sin líneas de comprobación. | H40: 3.5
A41: 26 | B41: M01A02cE06 | C41: Utilizando los conceptos aprendidos, dibuje las funciones trigonométricas en x de 0 a π (0 a 360 grados) con origen en (0,0). Luego, encuentre la escala proporcional de ajuste para que la longitud horizontal de las funciones trazadas, sea igual a sumatoria del último dígito de los códigos de alumno de su grupo, y escale las funciones a este tamaño. | D41: =_xlfn.IMAGE(_xlfn.CONCAT("https://github.com/rcfdtools/R.DAPC/blob/main/activity/",E41,"/graph/",B41,".jpg?raw=true")) -> #VALUE! | E41: M01A02c | F41: =HYPERLINK(_xlfn.CONCAT("https://github.com/rcfdtools/R.DAPC/blob/main/activity/",E41,"/Readme.md#ejercicio-",B41),"Ver") -> Ver | H41: 5
B43: 1.2.d. Dibujo en 3D (para la calificación de los ejercicios, el origen de las figuras 3D, deberá ser localizado en la esquina inferior izquierda del plano frontal de referencia y su coordenada absoluta X deberá desplazarse en una longitud correspondiente a la sumatoria del último dígito de los códigos de alumno de su grupo. Utilizar cero en las coordenadas Y,Z)
A45: 27 | B45: M01A02dE01 | C45: Construya el sólido mostrado en la figura, calcule el volúmen, área superficial, masa de cada elemento, volúmen y masa final del sólido integrado para material en titanio. | D45: =_xlfn.IMAGE(_xlfn.CONCAT("https://github.com/rcfdtools/R.DAPC/blob/main/activity/",E45,"/graph/",B45,".jpg?raw=true")) -> #VALUE! | E45: M01A02d | F45: =HYPERLINK(_xlfn.CONCAT("https://github.com/rcfdtools/R.DAPC/blob/main/activity/",E45,"/Readme.md#ejercicio-",B45),"Ver") -> Ver | G45: Sin cálculo de masa, material incorrecto. | H45: 4.5
A46: 28 | B46: M01A02dE02 | C46: A partir de la figura dibujada en el ejercicio M01A01E01, cree un sólido en acero y calcule su área superficial, volumen y masa. | D46: =_xlfn.IMAGE(_xlfn.CONCAT("https://github.com/rcfdtools/R.DAPC/blob/main/activity/",E46,"/graph/",B46,".jpg?raw=true")) -> #VALUE! | E46: M01A02d | F46: =HYPERLINK(_xlfn.CONCAT("https://github.com/rcfdtools/R.DAPC/blob/main/activity/",E46,"/Readme.md#ejercicio-",B46),"Ver") -> Ver | H46: 5
A47: 29 | B47: M01A02dE03 | C47: A partir de la figura ejemplo presentada en el numeral 6 de la actividad M01A01, cree un sólido en concreto y calcule su área superficial, volumen y masa. | D47: =_xlfn.IMAGE(_xlfn.CONCAT("https://github.com/rcfdtools/R.DAPC/blob/main/activity/",E47,"/graph/",B47,".jpg?raw=true")) -> #VALUE! | E47: M01A02d | F47: =HYPERLINK(_xlfn.CONCAT("https://github.com/rcfdtools/R.DAPC/blob/main/activity/",E47,"/Readme.md#ejercicio-",B47),"Ver") -> Ver | H47: 5
A48: 30 | B48: M01A02dE04 | C48: A partir de la figura ejemplo presentada en el numeral 6 de la actividad M01A01, cree un sólido en vidrio con aristas redondeadas y calcule su área superficial, volumen y masa. | D48: =_xlfn.IMAGE(_xlfn.CONCAT("https://github.com/rcfdtools/R.DAPC/blob/main/activity/",E48,"/graph/",B48,".jpg?raw=true")) -> #VALUE! | E48: M01A02d | F48: =HYPERLINK(_xlfn.CONCAT("https://github.com/rcfdtools/R.DAPC/blob/main/activity/",E48,"/Readme.md#ejercicio-",B48),"Ver") -> Ver | G48: Sin suavizado interno de aristas. Sin masa | H48: 4.25
A49: 31 | B49: M01A02dE05 | C49: A partir de la figura dibujada en el ejercicio M01A01E03, cree un sólido en aluminio y calcule su área superficial, volumen y masa. | D49: =_xlfn.IMAGE(_xlfn.CONCAT("https://github.com/rcfdtools/R.DAPC/blob/main/activity/",E49,"/graph/",B49,".jpg?raw=true")) -> #VALUE! | E49: M01A02d | F49: =HYPERLINK(_xlfn.CONCAT("https://github.com/rcfdtools/R.DAPC/blob/main/activity/",E49,"/Readme.md#ejercicio-",B49),"Ver") -> Ver | G49: Sin cálculo de masa, material incorrecto. | H49: 4.5
...

Sheet 1.Tecnica
B2: UECIJG / Dibujo asistido por computador - DAPC
B3: 1. Especificaciones técnicas generales
B4: En un proyecto, las especificaciones técnicas son documentos que detallan las normas, requisitos, procedimientos y condiciones técnicas que deben cumplirse en la ejecución de un proyecto. Estos documentos guían la implementación del proyecto, asegurando que se cumplan los estándares de calidad y se alcancen los resultados deseados.
B6: Especificación | C6: Descripción y alcance | D6: Valor | E6: Unidad | F6: Actividad | H6: Revisión | I6: Calificación
B7: Nombre de grupo y logotipo | C7: Los estudiantes deberán definir el nombre de su grupo de proyecto (utilice un nombre corporativo corto) y crear un logotipo en AutoCAD (guardar como /file/cad/logotipo.dwg). El código, logotipo y nombre del grupo deberán incluirse en todos los planos generados. El grupo se deberá mantener durante todo el semestre académico. Incorpore en el diseño del logotipo, una de las curvas especiales vistas. | D7: 1 | E7: Archivo | F7: M01A02c | G7: =HYPERLINK(_xlfn.CONCAT("https://github.com/rcfdtools/R.DAPC/blob/main/activity/",F7,"/Readme.md"),"Ver") -> Ver | H7: ElectraLine, con logotipo. Curva especial incorporada. | I7: 5
B8: Repositorio digital de proyecto | C8: Repositorio de datos creado, compartido y accesible. Crear en OneDrive de Campus. https://forms.office.com/r/gVg8DjvVFh | D8: 1 | E8: Repositorio | F8: M01A01 | G8: =HYPERLINK(_xlfn.CONCAT("https://github.com/rcfdtools/R.DAPC/blob/main/activity/",F8,"/Readme.md"),"Ver") -> Ver | H8: https://shorturl.at/8lPad | I8: 5
B9: Estructura de directorios | C9: Utilizar la estructura definida para el curso DAPC. | D9: Varios | F9: M01A01 | G9: =HYPERLINK(_xlfn.CONCAT("https://github.com/rcfdtools/R.DAPC/blob/main/activity/",F9,"/Readme.md"),"Ver") -> Ver | H9: Carpetas creadas y nombres correctos. | I9: 5
B10: Plantilla o layout - Archivo | C10: Guardar como /file/cad/DAPC.dwt | D10: 1 | E10: Archivo | F10: M01A05 | G10: =HYPERLINK(_xlfn.CONCAT("https://github.com/rcfdtools/R.DAPC/blob/main/activity/",F10,"/Readme.md"),"Ver") -> Ver | H10: Archivo DAPC.dwg. | I10: 5
B11: Plantilla o layout - Unidades de dibujo | C11: Lineales en metros, angulares en grados, precisión a dos decimales. | D11: Varios | F11: M01A01 | G11: =HYPERLINK(_xlfn.CONCAT("https://github.com/rcfdtools/R.DAPC/blob/main/activity/",F11,"/Readme.md"),"Ver") -> Ver | H11: Unidades correctas en DAPC.dwg. | I11: 5
B12: Plantilla o layout - Capas o layers | C12: Se deben utilizar los nombres de capas establecidos en la norma internacional estándar ISO-13567, aplicando las especificaciones del United States National CAD Stardard - v5 del National Institute of Building Sciences para los grupos A-Architectural, C-Civil, E-Electrical, S-Structural, V-Survey / Mapping y W-Distributed Energy. | D12: Varios | F12: M01A02a | G12: =HYPERLINK(_xlfn.CONCAT("https://github.com/rcfdtools/R.DAPC/blob/main/activity/",F12,"/Readme.md"),"Ver") -> Ver | H12: M01A02a.dwg con layers requeridas para el proyecto. | I12: 5
B13: Plantilla o layout - Acotado | C13: Crear estilos propios fijos y anotativos para las diferentes escalas de impresión a usar, utilizar el prefijo DAPC. | D13: Varios | F13: M01A04 | G13: =HYPERLINK(_xlfn.CONCAT("https://github.com/rcfdtools/R.DAPC/blob/main/activity/",F13,"/Readme.md"),"Ver") -> Ver | H13: Verificado en M01A04_1000105775.dwg. | I13: 5 | K13: Tercio 2
B14: Plantilla o layout - Formatos para impresión | C14: ISO-A0 / ISO-A4, horizontal y vertical. Formatos adicionales pueden ser incluídos en la plantilla. | D14: Varios | F14: M01A05 | G14: =HYPERLINK(_xlfn.CONCAT("https://github.com/rcfdtools/R.DAPC/blob/main/activity/",F14,"/Readme.md"),"Ver") -> Ver | H14: Verificado en M01A04_1000105775.dwg. | I14: 5 | K14: Tercio 2
B15: Bloques - arquitectónicos | C15: Utilizar los bloques ejemplo del ADC de AutoCAD, o utilizar una librería de bloque externos, citando la fuente de descarga. /file/cad/Bloque_Arquitectonico.dwg | D15: 1 | E15: Archivo | F15: M01A03 | G15: =HYPERLINK(_xlfn.CONCAT("https://github.com/rcfdtools/R.DAPC/blob/main/activity/",F15,"/Readme.md"),"Ver") -> Ver | H15: Puertas. Ventanas dibujadas manualmente. | I15: 5
B16: Bloques - eléctricos | C16: Para el dibujo de los planos eléctricos, utilizar los bloques creados a partir de las especificaciones establecidas en el Reglamento Técnico de Instalaciones Eléctricas - RETIE del Ministerio de Minas y Energía de Colombia. /file/cad/Bloque_Electrico.dwg | D16: 1 | E16: Archivo | F16: M01A03 | G16: =HYPERLINK(_xlfn.CONCAT("https://github.com/rcfdtools/R.DAPC/blob/main/activity/",F16,"/Readme.md"),"Ver") -> Ver | H16: 32 bloques de 48 bloques solicitados. Calificados como creación de figuras.
B17: Bloques - otros | C17: Utilizar una librería de bloque externos citando la fuente de descarga. Por ejemplo: cámaras de vigilancia, luces de emergencia, panel solar. /file/cad/Bloque_Otros.dwg | D17: 1 | E17: Archivo | F17: M01A03 | G17: =HYPERLINK(_xlfn.CONCAT("https://github.com/rcfdtools/R.DAPC/blob/main/activity/",F17,"/Readme.md"),"Ver") -> Ver | H17: No requeridos.
G18: =HYPERLINK(_xlfn.CONCAT("https://github.com/rcfdtools/R.DAPC/blob/main/activity/",F18,"/Readme.md"),"Ver") -> Ver
H19: Promedio: | I19: =AVERAGE(I7:I18) -> 5

Sheet 2.ArquitectonicaEstructural
B2: UECIJG / Dibujo asistido por computador - DAPC
B3: 2. Especificaciones arquitectónicas y estructurales
B4: En arquitectura, las especificaciones de un proyecto son documentos técnicos detallados que describen las características, materiales, estándares y métodos de construcción necesarios para ejecutar un proyecto. Estas especificaciones complementan los planos y proporcionan información precisa sobre cómo se deben realizar los trabajos, garantizando la calidad y cumplimiento de los requisitos.
B6: Especificación | C6: Descripción y alcance | D6: Valor | E6: Unidad | F6: Actividad | H6: Revisión | I6: Calificación
B7: 2a. Especificaciones generales e índices arquitectónicos
B8: Ancho de bodega - Referencia | C8: Valor de referencia para ancho de bodega. | D8: 8 | E8: m | F8: M01A01 | G8: =HYPERLINK(_xlfn.CONCAT("https://github.com/rcfdtools/R.DAPC/blob/main/activity/",F8,"/Readme.md"),"Ver") -> Ver | H8: Mantener este valor para el proyecto. Dibujo correcto. | I8: 5
B9: Largo de bodega - Referencia | C9: Valor de referencia para largo de bodega. | D9: 10 | E9: m | F9: M01A01 | G9: =HYPERLINK(_xlfn.CONCAT("https://github.com/rcfdtools/R.DAPC/blob/main/activity/",F9,"/Readme.md"),"Ver") -> Ver | H9: Mantener este valor para el proyecto. Dibujo correcto. | I9: 5
B10: Ancho de bodega - Proyecto | C10: Ancho de referencia + Σ del último dígito de los códigos de estudiante. En los laterales de la bodega no deben existir ventanas. | D10: =D8+SumUDig -> 34 | E10: m | F10: M01A01 | G10: =HYPERLINK(_xlfn.CONCAT("https://github.com/rcfdtools/R.DAPC/blob/main/activity/",F10,"/Readme.md"),"Ver") -> Ver | H10: Dibujo correcto. | I10: 5
B11: Largo de bodega - Proyecto | C11: Largo de referencia + Σ del último dígito de los códigos de estudiante. | D11: {=D9+SumUDig} -> 36 | E11: m | F11: M01A01 | G11: =HYPERLINK(_xlfn.CONCAT("https://github.com/rcfdtools/R.DAPC/blob/main/activity/",F11,"/Readme.md"),"Ver") -> Ver | H11: Dibujo correcto. | I11: 5
B12: Alto de bodega | C12: 1 nivel con altura de 12 metros y hasta la base de la cubierta. | D12: 12 | E12: m | F12: M01A01 | G12: =HYPERLINK(_xlfn.CONCAT("https://github.com/rcfdtools/R.DAPC/blob/main/activity/",F12,"/Readme.md"),"Ver") -> Ver | H12: Mantener este valor para el proyecto. Dibujo correcto. | I12: 5
B13: Aislamiento frontal | C13: Longitud del aíslamiento frontal a lo ancho del lote. | D13: 6 | E13: m | F13: M01A01 | G13: =HYPERLINK(_xlfn.CONCAT("https://github.com/rcfdtools/R.DAPC/blob/main/activity/",F13,"/Readme.md"),"Ver") -> Ver | H13: Mantener este valor para el proyecto. Dibujo correcto. | I13: 5
B14: Patio posterior | C14: Longitud del patio a lo ancho del lote. | D14: 12 | E14: m | F14: M01A01 | G14: =HYPERLINK(_xlfn.CONCAT("https://github.com/rcfdtools/R.DAPC/blob/main/activity/",F14,"/Readme.md"),"Ver") -> Ver | H14: Mantener este valor para el proyecto. Dibujo correcto. | I14: 5
B15: Ancho lote | C15: Ancho total del lote. Igual al ancho de la bodega debido a que no se permiten voladizos laterales ni sobre extensiones de la cubierta. | D15: =D10 -> 34 | E15: m | F15: M01A01 | G15: =HYPERLINK(_xlfn.CONCAT("https://github.com/rcfdtools/R.DAPC/blob/main/activity/",F15,"/Readme.md"),"Ver") -> Ver | H15: Dibujo correcto. | I15: 5
B16: Largo lote | C16: Largo total del lote incluyendo patio posterior. | D16: =D11+D14+D13 -> 54 | E16: m | F16: M01A01 | G16: =HYPERLINK(_xlfn.CONCAT("https://github.com/rcfdtools/R.DAPC/blob/main/activity/",F16,"/Readme.md"),"Ver") -> Ver | H16: Dibujo correcto. | I16: 5
B17: Área lote | C17: Área total del lote, no deben existir elementos constructivos fuera del polígono que inscribe esta área. | D17: =D16*D15 -> 1836 | E17: m² | F17: M01A01 | G17: =HYPERLINK(_xlfn.CONCAT("https://github.com/rcfdtools/R.DAPC/blob/main/activity/",F17,"/Readme.md"),"Ver") -> Ver | H17: Dibujo correcto. | I17: 5
B18: Área ocupada | C18: Área ocupada bajo cubiertas. | D18: =D32+D30 -> 1360 | E18: m² | F18: M01A01 | G18: =HYPERLINK(_xlfn.CONCAT("https://github.com/rcfdtools/R.DAPC/blob/main/activity/",F18,"/Readme.md"),"Ver") -> Ver | I18: 5
B19: Área construída | C19: Área construída bajo cubierta más área de mezanine. | D19: =D32+D30+D51 -> 1420 | E19: m² | F19: M01A01 | G19: =HYPERLINK(_xlfn.CONCAT("https://github.com/rcfdtools/R.DAPC/blob/main/activity/",F19,"/Readme.md"),"Ver") -> Ver | I19: 5
B20: Índice de ocupación | C20: Corresponde a la división del área ocupada bajo cubiertas entre el área del lote. No incluir las zonas duras externas que no están bajo cubierta. El resultado siempre es menor o igual a 1. | D20: =D18/D17 -> 0.74074074 | E20: Adim. | F20: M01A01 | G20: =HYPERLINK(_xlfn.CONCAT("https://github.com/rcfdtools/R.DAPC/blob/main/activity/",F20,"/Readme.md"),"Ver") -> Ver | I20: 5
B21: Índice de construcción | C21: Corresponde a la división del área construída bajo cubiertas entre el área del lote. El resultado puede ser mayor a 1. | D21: =D19/D17 -> 0.77342048 | E21: Adim. | F21: M01A01 | G21: =HYPERLINK(_xlfn.CONCAT("https://github.com/rcfdtools/R.DAPC/blob/main/activity/",F21,"/Readme.md"),"Ver") -> Ver | I21: 5
G22: =HYPERLINK(_xlfn.CONCAT("https://github.com/rcfdtools/R.DAPC/blob/main/activity/",F22,"/Readme.md"),"Ver") -> Ver
B23: 2b. Diseño de cubierta (dibujo y diseño a partir de la altura de la bodega)
B24: Voladizo | C24: Láminas metálicas sobre estructura metálica. La cubierta no deberá sobre salir mas allá del ancho del lote. Incluir voladizo frontal y posterior. Libre elección: a un agua, a dos aguas o en domo. | D24: 2 | E24: m | F24: M01A01 | G24: =HYPERLINK(_xlfn.CONCAT("https://github.com/rcfdtools/R.DAPC/blob/main/activity/",F24,"/Readme.md"),"Ver") -> Ver | H24: Mantener este valor para el proyecto. Dibujo correcto. | I24: 5
B25: Pendiente en % | C25: Pendiente mínima de inclinación de la cubierta para asegurar el buen drenaje del agua provendiente de la lluvia o precipitación. Cómo referencia, para láminas metálicas continuas, algunos fabricantes recomiendan pendientes tan bajas como 2%, mientras que para cubiertas con solapes, se sugiere una pendiente mínima del 10% para evitar filtraciones. | D25: 5.2407676 | E25: % | F25: M01A01 | G25: =HYPERLINK(_xlfn.CONCAT("https://github.com/rcfdtools/R.DAPC/blob/main/activity/",F25,"/Readme.md"),"Ver") -> Ver | H25: Dibujo correcto. | I25: 5
B26: Pendiente en ° | C26: Por cada unidad horizontal, la cubierta se eleva el % indicado, p. ej., si la pendiente es del 100% el ángulo de inclinación es de 45°, lo que significa que por cada unidad horizontal, la cubierta se eleva el mismo valor. Redondear al entero más cercano. | D26: =ATAN(D25/100)*180/PI() -> 2.9999941 | E26: ° | F26: M01A01 | G26: =HYPERLINK(_xlfn.CONCAT("https://github.com/rcfdtools/R.DAPC/blob/main/activity/",F26,"/Readme.md"),"Ver") -> Ver | H26: Dibujo correcto. | I26: 5
B27: Viga canal - Ancho | C27: A los costados y a lo ancho de la cubierta (incluídos voladizos), se deben dibujar canales de recolección de aguas lluvias, como mínimo 0.4 metros. Ver nota 1a. | D27: 0.6 | E27: m | F27: M01A01 | G27: =HYPERLINK(_xlfn.CONCAT("https://github.com/rcfdtools/R.DAPC/blob/main/activity/",F27,"/Readme.md"),"Ver") -> Ver | H27: Dibujo correcto. | I27: 5
B28: Viga canal - Sobrelapado de cubierta | C28: La cubierta debe descargar sobre la viga canal lateral a los costados utilizando sobrelapado. | D28: 0.2 | E28: m | F28: M01A01 | G28: =HYPERLINK(_xlfn.CONCAT("https://github.com/rcfdtools/R.DAPC/blob/main/activity/",F28,"/Readme.md"),"Ver") -> Ver | H28: Dibujo correcto. | I28: 5
B29: Viga canal - Costados | C29: 1 para solo vigacanal localizada a un costado, 2 para ambos costados. | D29: 2 | E29: Adim. | F29: M01A01 | G29: =HYPERLINK(_xlfn.CONCAT("https://github.com/rcfdtools/R.DAPC/blob/main/activity/",F29,"/Readme.md"),"Ver") -> Ver | H29: Tejado a dos aguas. | I29: 5
B30: Viga canal - Área fuera de cubierta | C30: Área canal descontable del total de la cubierta. Ancho de canal menos el sobrelapo x largo de la cubierta y por # de costados. | D30: =(D27-D28)*(D11+D24+D24)*D29 -> 32 | E30: m² | F30: M01A01 | G30: =HYPERLINK(_xlfn.CONCAT("https://github.com/rcfdtools/R.DAPC/blob/main/activity/",F30,"/Readme.md"),"Ver") -> Ver | H30: Dibujo correcto. | I30: 5
B31: Área cubierta sin voladizo y hasta sobrelapo viga canal | C31: Láminas metálicas sobre estructura metálica. La cubierta no deberá sobre salir mas allá del ancho del lote. Descontar la fracción correspondiente a la viga canal lateral. | D31: =(D10*D11)-D30 -> 1192 | E31: m² | F31: M01A01 | G31: =HYPERLINK(_xlfn.CONCAT("https://github.com/rcfdtools/R.DAPC/blob/main/activity/",F31,"/Readme.md"),"Ver") -> Ver | H31: Dibujo correcto. | I31: 5
B32: Área cubierta con voladizo y hasta sobrelapo viga canal | C32: Láminas metálicas sobre estructura metálica. La cubierta no deberá sobre salir mas allá del ancho del lote. Incluir voladizo frontal y posterior. Este valor corresponde al área ocupada en el lote. Descontar la fracción correspondiente a la viga canal lateral. | D32: =((D10*D11)+D10*(D24+D24))-D30 -> 1328 | E32: m² | F32: M01A01 | G32: =HYPERLINK(_xlfn.CONCAT("https://github.com/rcfdtools/R.DAPC/blob/main/activity/",F32,"/Readme.md"),"Ver") -> Ver | H32: Dibujo correcto. | I32: 5
B33: Ventiladores - Separación de diseño | C33: Incluir ventiladores eléctricos axiales industriales para extracción de aire caliente utilizando la separación indicada. | D33: 8 | E33: m | F33: M01A02b | G33: =HYPERLINK(_xlfn.CONCAT("https://github.com/rcfdtools/R.DAPC/blob/main/activity/",F33,"/Readme.md"),"Ver") -> Ver | H33: Dibujo correcto. | I33: 5
B34: Ventiladores - Cantidad total requerida | C34: La cantidad requerida de ventiladores es igual al área total de la cubierta sin voladizos dividido entre la separación² de los ventiladores. Evaluar en números pares. Se analiza únicamente con el área interna de la cubierta y sin los voladizos. | D34: =EVEN(D31/(D33*D33)) -> 20 | E34: Un. | F34: M01A02b | G34: =HYPERLINK(_xlfn.CONCAT("https://github.com/rcfdtools/R.DAPC/blob/main/activity/",F34,"/Readme.md"),"Ver") -> Ver | H34: 20 en dibujo. | I34: 5
B35: Ventiladores - Cantidad a lo ancho | C35: # de ventiladores a lo ancho de la bodega. | D35: =(INT(D10/D33)) -> 4 | H35: Distribución correcta. | I35: 5
B36: Ventiladores - Cantidad a lo largo | C36: # de ventiladores a lo largo de la bodega. | D36: =D34/D35 -> 5 | H36: Buscar un valor entero cambiando la separación de diseño. Distribución correcta. | I36: 5
B37: Ventiladores - Separación a lo ancho | C37: Separación de ventiladores a lo ancho de la bodega. | D37: =D10/(D35+1) -> 6.8 | E37: m | F37: M01A02b | G37: =HYPERLINK(_xlfn.CONCAT("https://github.com/rcfdtools/R.DAPC/blob/main/activity/",F37,"/Readme.md"),"Ver") -> Ver | H37: 8 metros, cumple separación de diseño. | I37: 5
B38: Ventiladores - Separación a lo largo | C38: Separación de ventiladores a lo largo de la bodega y sin el voladizo. | D38: =D11/(D36+1) -> 6 | E38: m | F38: M01A02b | G38: =HYPERLINK(_xlfn.CONCAT("https://github.com/rcfdtools/R.DAPC/blob/main/activity/",F38,"/Readme.md"),"Ver") -> Ver | H38: 7.2 metros, cumple separación de diseño. | I38: 5
B39: Ventiladores - Diámetro ØC | C39: Ver especificaciones técnicas en archivo /file/ref/FT_D37-AXP-AXD-AXM-104.pdf. | D39: 1200 | E39: mm | F39: M01A02b | G39: =HYPERLINK(_xlfn.CONCAT("https://github.com/rcfdtools/R.DAPC/blob/main/activity/",F39,"/Readme.md"),"Ver") -> Ver | H39: Dibujo correcto. | I39: 5
B40: Ventiladores - Área por ventilador | C40: Ver especificaciones técnicas en archivo /file/ref/FT_D37-AXP-AXD-AXM-104.pdf. Utilizar cuadrado con lado igual al diametro externo ØC. Dibujar elemento en planta y en alzado usando líneas y curvas. | D40: =D39*D39/(1000*1000) -> 1.44 | E40: m² | F40: M01A02b | G40: =HYPERLINK(_xlfn.CONCAT("https://github.com/rcfdtools/R.DAPC/blob/main/activity/",F40,"/Readme.md"),"Ver") -> Ver | H40: Dibujo correcto. | I40: 5
B41: Ventiladores - Área total ventiladores | C41: Se calcula con el número de ventiladores x área de cada ventilador. | D41: =D34*D40 -> 28.8 | E41: m² | F41: M01A02b | G41: =HYPERLINK(_xlfn.CONCAT("https://github.com/rcfdtools/R.DAPC/blob/main/activity/",F41,"/Readme.md"),"Ver") -> Ver | H41: Dibujo correcto. | I41: 5
G42: =HYPERLINK(_xlfn.CONCAT("https://github.com/rcfdtools/R.DAPC/blob/main/activity/",F42,"/Readme.md"),"Ver") -> Ver
...

Sheet 2.ArquitectonicaEstructuralCAD
B2: Secuencias de comando CAD para dibujo de elementos
B3: Elementos en planta (dibujados en sentido horario)
B4: Lote | C4: Bodega | D4: Cubierta
B5: LINE | C5: LINE | D5: LINE
B6: =_xlfn.CONCAT(SumUDig,",",SumUDig) -> 26,26 | C6: =_xlfn.CONCAT(SumUDig,",",SumUDig+'2.ArquitectonicaEstructural'!D13) -> 26,32 | D6: =_xlfn.CONCAT(SumUDig,",",SumUDig+'2.ArquitectonicaEstructural'!D13-'2.ArquitectonicaEstructural'!D24) -> 26,30
B7: =_xlfn.CONCAT("@",'2.ArquitectonicaEstructural'!D15,",",0) -> @34,0 | C7: =_xlfn.CONCAT("@",'2.ArquitectonicaEstructural'!D10,",",0) -> @34,0 | D7: =_xlfn.CONCAT("@",'2.ArquitectonicaEstructural'!D10,",",0) -> @34,0
B8: =_xlfn.CONCAT("@0,",'2.ArquitectonicaEstructural'!D16) -> @0,54 | C8: =_xlfn.CONCAT("@0,",'2.ArquitectonicaEstructural'!D11) -> @0,36 | D8: =_xlfn.CONCAT("@0,",'2.ArquitectonicaEstructural'!D11+2*'2.ArquitectonicaEstructural'!D24) -> @0,40
B9: =_xlfn.CONCAT("@",-'2.ArquitectonicaEstructural'!D15,",",0) -> @-34,0 | C9: =_xlfn.CONCAT("@",-'2.ArquitectonicaEstructural'!D10,",",0) -> @-34,0 | D9: =_xlfn.CONCAT("@",-'2.ArquitectonicaEstructural'!D10,",",0) -> @-34,0
B10: =_xlfn.CONCAT("@0,",-'2.ArquitectonicaEstructural'!D16) -> @0,-54 | C10: =_xlfn.CONCAT("@0,",-'2.ArquitectonicaEstructural'!D11) -> @0,-36 | D10: =_xlfn.CONCAT("@0,",-('2.ArquitectonicaEstructural'!D11+2*'2.ArquitectonicaEstructural'!D24)) -> @0,-40

Sheet 3.Electrica
B2: UECIJG / Dibujo asistido por computador - DAPC
B3: 3. Especificaciones eléctricas
B4: En un proyecto, las especificaciones eléctricas son un conjunto de directrices técnicas que describen detalladamente las características y requisitos de los componentes y equipos eléctricos que se utilizarán. Estas especificaciones aseguran que la instalación eléctrica sea segura, confiable y cumpla con los estándares y normativas aplicables.
B6: Especificación | C6: Descripción y alcance | D6: Valor | E6: Unidad | F6: Actividad | H6: Revisión | I6: Calificación
B7: 3a. Especificaciones generales y redes o instalaciones (en este curso, no es necesario crear los planos de instalaciones hidráulicas, sanitarias y contra incendios)
B8: Acometida eléctrica | C8: Utilizando las especificaciones del Reglamento Técnico de Instalaciones Eléctricas - RETIE del Ministerio de Minas y Energía de Colombia, dibuje la acometida eléctrica. Dibujar en planta y en cortes. Esquema solo en planta. Conexión desde poste o subterránea desde lindero de entrada al predio en uno de los laterales. | D8: 1 | E8: Un. | F8: M01A03 | G8: =HYPERLINK(_xlfn.CONCAT("https://github.com/rcfdtools/R.DAPC/blob/main/activity/",F8,"/Readme.md"),"Ver") -> Ver | H8: Dibujada sobre puerta de entrada a oficinal. Mover a muro frontal cerca del tablero eléctrico. | I8: 5 | K8: Tercio 2
B9: Red eléctrica interna 110v* | C9: Esquema solo en planta. Redes eléctricas internas. | D9: 1 | E9: Un. | F9: M01A03 | G9: =HYPERLINK(_xlfn.CONCAT("https://github.com/rcfdtools/R.DAPC/blob/main/activity/",F9,"/Readme.md"),"Ver") -> Ver | I9: 5 | K9: Tercio 2
B10: Red eléctrica interna 220v* | C10: Esquema solo en planta. Redes eléctricas internas. | D10: 1 | E10: Un. | F10: M01A03 | G10: =HYPERLINK(_xlfn.CONCAT("https://github.com/rcfdtools/R.DAPC/blob/main/activity/",F10,"/Readme.md"),"Ver") -> Ver | H10: Opcional. | K10: Tercio 2
B11: Red de datos usando cableado* | C11: Esquema solo en planta. Red de datos en zona de oficinas y puntos generales de localización de equipos de cómputo, repetidores wi-fi y cámaras. | D11: 1 | E11: Un. | F11: M01A03 | G11: =HYPERLINK(_xlfn.CONCAT("https://github.com/rcfdtools/R.DAPC/blob/main/activity/",F11,"/Readme.md"),"Ver") -> Ver | H11: Opcional. | K11: Tercio 2
B12: Red foto-voltáica* | C12: Esquema solo en planta. Líneas de conexión de páneles y unión a acumuladores e inversores. Localizar cerca del tablero eléctrico. | D12: 1 | E12: Un. | F12: M01A03 | G12: =HYPERLINK(_xlfn.CONCAT("https://github.com/rcfdtools/R.DAPC/blob/main/activity/",F12,"/Readme.md"),"Ver") -> Ver | H12: Distibución de páneles en cubierta. | I12: 5 | K12: Tercio 2
B13: Red vigilancia* | C13: Esquema solo en planta. Localización de cámaras de seguridad. | D13: 1 | E13: Un. | F13: M01A03 | G13: =HYPERLINK(_xlfn.CONCAT("https://github.com/rcfdtools/R.DAPC/blob/main/activity/",F13,"/Readme.md"),"Ver") -> Ver | I13: 5 | K13: Tercio 2
B14: Tomacorrientes | C14: Localizados en planta y en cortes. | D14: 1 | E14: Un. | F14: M01A03 | G14: =HYPERLINK(_xlfn.CONCAT("https://github.com/rcfdtools/R.DAPC/blob/main/activity/",F14,"/Readme.md"),"Ver") -> Ver | I14: 5 | K14: Tercio 2
B15: Interruptores | C15: Localizados en planta y en cortes. | D15: 1 | E15: Un. | F15: M01A03 | G15: =HYPERLINK(_xlfn.CONCAT("https://github.com/rcfdtools/R.DAPC/blob/main/activity/",F15,"/Readme.md"),"Ver") -> Ver | I15: 5 | K15: Tercio 2
B16: Luminarias | C16: Localizados en planta y en cortes. | D16: 1 | E16: Un. | F16: M01A03 | G16: =HYPERLINK(_xlfn.CONCAT("https://github.com/rcfdtools/R.DAPC/blob/main/activity/",F16,"/Readme.md"),"Ver") -> Ver | I16: 5 | K16: Tercio 2
B17: Cámaras de vigilancia | C17: Localizados en planta y en cortes. | D17: 1 | E17: Un. | F17: M01A03 | G17: =HYPERLINK(_xlfn.CONCAT("https://github.com/rcfdtools/R.DAPC/blob/main/activity/",F17,"/Readme.md"),"Ver") -> Ver | I17: 5 | K17: Tercio 2
B18: Luces de emergencia | C18: Localizados en planta y en cortes. | D18: 1 | E18: Un. | F18: M01A03 | G18: =HYPERLINK(_xlfn.CONCAT("https://github.com/rcfdtools/R.DAPC/blob/main/activity/",F18,"/Readme.md"),"Ver") -> Ver | H18: Opcional. | K18: Tercio 2
B19: Pararrayos | C19: Localizados en planta y en cortes. Dibujar en 2D y 3D. Actividades M01A02b y M01A02d. Presente los elementos directrices para la generación del elemento 3D. | D19: 1 | E19: Un. | F19: M01A02d | G19: =HYPERLINK(_xlfn.CONCAT("https://github.com/rcfdtools/R.DAPC/blob/main/activity/",F19,"/Readme.md"),"Ver") -> Ver | H19: Informe sin investigación de qué es y para que sirve un pararrayos. Incorporar el pararrayos en el archivo del proyecto DAPC.dwg | I19: 4.5 | K19: Tercio 2
B20: Polo a tierra | C20: Localizados en planta y en cortes. | D20: 1 | E20: Un. | F20: M01A03 | G20: =HYPERLINK(_xlfn.CONCAT("https://github.com/rcfdtools/R.DAPC/blob/main/activity/",F20,"/Readme.md"),"Ver") -> Ver | I20: 5 | K20: Tercio 2
G21: =HYPERLINK(_xlfn.CONCAT("https://github.com/rcfdtools/R.DAPC/blob/main/activity/",F21,"/Readme.md"),"Ver") -> Ver | K21: Tercio 2
B22: 3b. Energía solar (evaluar únicamente el número de páneles que se pueden instalar y dibujarlos sobre la cubierta)
B23: Área disponible en cubierta | C23: Del área total de la cubierta debe restar los espacios para las pasarelas de instalación y mantenimiento, líneas de vída y ventiladores eléctricos industriales. Solo se instalan en el área de cubierta sin voladizos. | D23: ='2.ArquitectonicaEstructural'!D31-'2.ArquitectonicaEstructural'!D41-'2.ArquitectonicaEstructural'!D47 -> 1059.2 | E23: m² | F23: M01A01 | G23: =HYPERLINK(_xlfn.CONCAT("https://github.com/rcfdtools/R.DAPC/blob/main/activity/",F23,"/Readme.md"),"Ver") -> Ver | I23: 5 | K23: Tercio 2
B24: Panel solar - Ancho | C24: Ancho del pánel, utilizar medida estándar para pánel industrial. | D24: 992 | E24: mm | F24: M01A01 | G24: =HYPERLINK(_xlfn.CONCAT("https://github.com/rcfdtools/R.DAPC/blob/main/activity/",F24,"/Readme.md"),"Ver") -> Ver | I24: 5 | K24: Tercio 2
B25: Panel solar - Largo | C25: Largo del pánel, utilizar medida estándar para pánel industrial. | D25: 1950 | E25: mm | F25: M01A01 | G25: =HYPERLINK(_xlfn.CONCAT("https://github.com/rcfdtools/R.DAPC/blob/main/activity/",F25,"/Readme.md"),"Ver") -> Ver | I25: 5 | K25: Tercio 2
B26: # de páneles | C26: Área disponible en cubierta / área por pánel. Calcular como valor entero debido a que los páneles son unidades selladas. El número de páneles debe ser verificado dibujando su localización y verificando que queden embebidos dentro de las áreas remanentes de la cubierta. | D26: =INT(D23/(D24/1000*D25/1000)) -> 547 | E26: Un. | F26: M01A01 | G26: =HYPERLINK(_xlfn.CONCAT("https://github.com/rcfdtools/R.DAPC/blob/main/activity/",F26,"/Readme.md"),"Ver") -> Ver | I26: 5 | K26: Tercio 2
G27: =HYPERLINK(_xlfn.CONCAT("https://github.com/rcfdtools/R.DAPC/blob/main/activity/",F27,"/Readme.md"),"Ver") -> Ver
H28: Promedio: | I28: =AVERAGE(I7:I27) -> 4.9642857
B29: * Incluya notas descriptivas de localización del conducto, tubería o canaleta, utilice los siguientes códigos:
B30: Nota de localización | C30: Descripción
B31: Tpp | C31: Embebida por placa o piso.
B32: Tpc | C32: Por cielorraso, anclada o descolgada.
B33: Tpm | C33: Embebida en muro.
B34: Tam | C34: Anclada a muro
B35: Tdt | C35: Descolgada sin cielorraso.
B37: * Seguido de la nota descriptiva de localización, indique el material, utilice los siguientes códigos:
B38: Material | C38: Descripción
B39: PVC | C39: Plástica en policloruro de vinilo.
B40: Polietileno | C40: Polímero termoplástico.
B41: RTRC | C41: Fibra de vidrio. Reinforced Thermosetting Resin Conduit.
B42: Polipropileno o nylon | C42: Resistente a alta temperatura
B43: Acero Galv. | C43: Metálica en acero galvanizado.
...

Sheet 4.Bodegaje
B2: UECIJG / Dibujo asistido por computador - DAPC
B3: 4. Bodegaje
B4: La distribución de una bodega en un proyecto implica planificar la disposición de las áreas y elementos para optimizar el flujo de materiales, maximizar el espacio y garantizar la eficiencia operativa. Se deben considerar factores como el tipo de productos, la rotación, el tamaño del almacén y los equipos de manipulación.
B6: Especificación | C6: Descripción y alcance | D6: Valor | E6: Unidad | F6: Actividad | H6: Revisión | I6: Calificación
B7: 4a. Estantería industrial
B8: Separación entre estantes | C8: Separación o ancho del corredor por donde se desplaza el montacargas industrial. | D8: 3 | E8: m | F8: M01A03 | G8: =HYPERLINK(_xlfn.CONCAT("https://github.com/rcfdtools/R.DAPC/blob/main/activity/",F8,"/Readme.md"),"Ver") -> Ver | H8: Verificado con M01A04_1000105775.dwg y tabla. | I8: 5 | K8: Tercio 2
B9: Ancho de estante | C9: Ancho total del estante. En zonas internas se pueden colocar en hileras de dos, en costados de bodega solo una hilera. | D9: 2.5 | E9: m | F9: M01A03 | G9: =HYPERLINK(_xlfn.CONCAT("https://github.com/rcfdtools/R.DAPC/blob/main/activity/",F9,"/Readme.md"),"Ver") -> Ver | H9: Verificado con M01A04_1000105775.dwg y tabla. | I9: 5 | K9: Tercio 2
B10: Número de niveles en estantes | C10: Corresponde al número de pisos que tendrá la estantería incluído el piso a nivel de placa. | D10: 3 | E10: Nivel | F10: M01A03 | G10: =HYPERLINK(_xlfn.CONCAT("https://github.com/rcfdtools/R.DAPC/blob/main/activity/",F10,"/Readme.md"),"Ver") -> Ver | H10: Verificado con M01A04_1000105775.dwg y tabla. | I10: 5 | K10: Tercio 2
B11: Alto de entrepiso en estante | C11: Altura del entrepiso incluyendo el espesor de la base. | D11: 2 | E11: m | F11: M01A03 | G11: =HYPERLINK(_xlfn.CONCAT("https://github.com/rcfdtools/R.DAPC/blob/main/activity/",F11,"/Readme.md"),"Ver") -> Ver | H11: Verificado con M01A04_1000105775.dwg y tabla. | I11: 5 | K11: Tercio 2
B12: Elevación de piso del último estante | C12: Esta elevación no debe ser superior a la altura vertical de desplazamiento del montacarga. | D12: =D10*D11 -> 6 | E12: m | F12: M01A03 | G12: =HYPERLINK(_xlfn.CONCAT("https://github.com/rcfdtools/R.DAPC/blob/main/activity/",F12,"/Readme.md"),"Ver") -> Ver | H12: Verificado con M01A04_1000105775.dwg y tabla. | I12: 5 | K12: Tercio 2
B13: Altura máxima de montacargas | C13: Altura máxima que puede elevar el montacargas, requerido para definir la altura superior de la estantería. | D13: 8 | E13: m | F13: M01A03 | G13: =HYPERLINK(_xlfn.CONCAT("https://github.com/rcfdtools/R.DAPC/blob/main/activity/",F13,"/Readme.md"),"Ver") -> Ver | H13: Verificado con M01A04_1000105775.dwg y tabla. | I13: 5 | K13: Tercio 2
B14: Verificación de montacarga | C14: Verificación de desplazamiento para carga y descarga del montacargas. | D14: =IF(D12<=D13, "Cumple","No cumple") -> Cumple | E14: n/a | F14: M01A03 | G14: =HYPERLINK(_xlfn.CONCAT("https://github.com/rcfdtools/R.DAPC/blob/main/activity/",F14,"/Readme.md"),"Ver") -> Ver | H14: Verificado con M01A04_1000105775.dwg y tabla. | I14: 5 | K14: Tercio 2
B15: Longitud total de estantería en planta | C15: Distribuir dentro de la bodeda y medir. | D15: 416.646 | E15: m | F15: M01A03 | G15: =HYPERLINK(_xlfn.CONCAT("https://github.com/rcfdtools/R.DAPC/blob/main/activity/",F15,"/Readme.md"),"Ver") -> Ver | H15: Verificado con M01A04_1000105775.dwg y tabla. | I15: 5 | K15: Tercio 2
B16: Longitud total de estantería en todos los niveles | C16: Valor longitudinal por número de niveles. | D16: =D15*D10 -> 1249.938 | E16: m | F16: M01A03 | G16: =HYPERLINK(_xlfn.CONCAT("https://github.com/rcfdtools/R.DAPC/blob/main/activity/",F16,"/Readme.md"),"Ver") -> Ver | H16: Verificado con M01A04_1000105775.dwg y tabla. | I16: 5 | K16: Tercio 2
G17: =HYPERLINK(_xlfn.CONCAT("https://github.com/rcfdtools/R.DAPC/blob/main/activity/",F17,"/Readme.md"),"Ver") -> Ver
B18: 4b. Inventario (al menos se deben incluir 3 referencias distintas de transformadores eléctricos industriales)
B19: Transformador 1 - Ref: Transformador Trifásico Seco de 1 600 kVA – Clase H | C19: Indique la referencia y cantidad de elementos a almacenar en la bodega. Para la distribución en estantes, los transformadores grandes se almacenan en la parte inferior, los medianos en los estantes intermedios y los livianos en la parte superior. | D19: 99 | E19: Un. | F19: M01A03 | G19: =HYPERLINK(_xlfn.CONCAT("https://github.com/rcfdtools/R.DAPC/blob/main/activity/",F19,"/Readme.md"),"Ver") -> Ver | H19: Verificado en libro de Excel en carpeta /table. | I19: 5 | K19: Tercio 2
B20: Transformador 2 - Ref: Transformador Trifásico Baja-Baja de 500 kVA | C20: Indique la referencia y cantidad de elementos a almacenar en la bodega. Para la distribución en estantes, los transformadores grandes se almacenan en la parte inferior, los medianos en los estantes intermedios y los livianos en la parte superior. | D20: 137 | E20: Un. | F20: M01A03 | G20: =HYPERLINK(_xlfn.CONCAT("https://github.com/rcfdtools/R.DAPC/blob/main/activity/",F20,"/Readme.md"),"Ver") -> Ver | H20: Verificado en libro de Excel en carpeta /table. | I20: 5 | K20: Tercio 2
