Workbook
Name a_elipse: ElipseTabla!$D$8
Name a_hiperbola: HiperbolaTabla!$D$8
Name a_superelipse: SuperElipseTabla!$D$7
Name b_elipse: ElipseTabla!$D$9
Name b_hiperbola: HiperbolaTabla!$D$9
Name b_superelipse: SuperElipseTabla!$D$8
Name h_elipse: ElipseTabla!$D$6
Name h_superelipse: SuperElipseTabla!#REF!
Name k_elipse: ElipseTabla!$D$7
Name k_superelipse: SuperElipseTabla!#REF!
Name n_superelipse: SuperElipseTabla!$D$6
Name np_elipse: ElipseTabla!$D$10
Name np_hiperbola: HiperbolaTabla!$D$10
Name np_superelipse: SuperElipseTabla!$D$9
Name xend_hiperbola: HiperbolaTabla!$D$7
Name xstart_hiperbola: HiperbolaTabla!$D$6

Sheet ElipseTabla
H1: v.20250701
B3: Dibujo de Elipse con centro en (h,k)
B5: Parámetro | D5: Valor
B6: Centroide en x, h | D6: 100
B7: Centroide en y, k | D7: 50
B8: Semieje mayor, a | D8: 60
B9: Semieje menor, b | D9: 20
B10: Puntos por cuadrante | D10: 99
B11: Foco, c ± | D11: =IF(a_elipse>b_elipse,(a_elipse^2-b_elipse^2)^0.5,(b_elipse^2-a_elipse^2)^0.5) -> 56.568542
B12: Excentricidad, e | D12: =D11/a_elipse -> 0.94280904
B13: Nodo | C13: X | D13: YC1 | E13: YC2 | F13: -X | G13: YC3 | H13: YC4
B14: 1 | C14: =h_elipse -> 100 | D14: =(((1-(($C14-h_elipse)^2/a_elipse^2))*(b_elipse^2))^0.5)+k_elipse -> 70 | E14: =k_elipse-b_elipse -> 30 | F14: =C14 -> 100 | G14: =D14 -> 70 | H14: =E14 -> 30
B15: 2 | C15: =IF((a_elipse/np_elipse)+C14>=h_elipse+a_elipse,h_elipse+a_elipse,(a_elipse/np_elipse)+C14) -> 100.60606 | D15: =(((1-(($C15-h_elipse)^2/a_elipse^2))*(b_elipse^2))^0.5)+k_elipse -> 69.99898 | E15: =E14+(D14-D15) -> 30.00102 | F15: =(F14-(C15-C14)) -> 99.393939 | G15: =D15 -> 69.99898 | H15: =E15 -> 30.00102
B16: 3 | C16: =IF((a_elipse/np_elipse)+C15>=h_elipse+a_elipse,h_elipse+a_elipse,(a_elipse/np_elipse)+C15) -> 101.21212 | D16: =(((1-(($C16-h_elipse)^2/a_elipse^2))*(b_elipse^2))^0.5)+k_elipse -> 69.995918 | E16: =E15+(D15-D16) -> 30.004082 | F16: =(F15-(C16-C15)) -> 98.787879 | G16: =D16 -> 69.995918 | H16: =E16 -> 30.004082
B17: 4 | C17: =IF((a_elipse/np_elipse)+C16>=h_elipse+a_elipse,h_elipse+a_elipse,(a_elipse/np_elipse)+C16) -> 101.81818 | D17: =(((1-(($C17-h_elipse)^2/a_elipse^2))*(b_elipse^2))^0.5)+k_elipse -> 69.990815 | E17: =E16+(D16-D17) -> 30.009185 | F17: =(F16-(C17-C16)) -> 98.181818 | G17: =D17 -> 69.990815 | H17: =E17 -> 30.009185
B18: 5 | C18: =IF((a_elipse/np_elipse)+C17>=h_elipse+a_elipse,h_elipse+a_elipse,(a_elipse/np_elipse)+C17) -> 102.42424 | D18: =(((1-(($C18-h_elipse)^2/a_elipse^2))*(b_elipse^2))^0.5)+k_elipse -> 69.983668 | E18: =E17+(D17-D18) -> 30.016332 | F18: =(F17-(C18-C17)) -> 97.575758 | G18: =D18 -> 69.983668 | H18: =E18 -> 30.016332
B19: 6 | C19: =IF((a_elipse/np_elipse)+C18>=h_elipse+a_elipse,h_elipse+a_elipse,(a_elipse/np_elipse)+C18) -> 103.0303 | D19: =(((1-(($C19-h_elipse)^2/a_elipse^2))*(b_elipse^2))^0.5)+k_elipse -> 69.974476 | E19: =E18+(D18-D19) -> 30.025524 | F19: =(F18-(C19-C18)) -> 96.969697 | G19: =D19 -> 69.974476 | H19: =E19 -> 30.025524
B20: 7 | C20: =IF((a_elipse/np_elipse)+C19>=h_elipse+a_elipse,h_elipse+a_elipse,(a_elipse/np_elipse)+C19) -> 103.63636 | D20: =(((1-(($C20-h_elipse)^2/a_elipse^2))*(b_elipse^2))^0.5)+k_elipse -> 69.963235 | E20: =E19+(D19-D20) -> 30.036765 | F20: =(F19-(C20-C19)) -> 96.363636 | G20: =D20 -> 69.963235 | H20: =E20 -> 30.036765
B21: 8 | C21: =IF((a_elipse/np_elipse)+C20>=h_elipse+a_elipse,h_elipse+a_elipse,(a_elipse/np_elipse)+C20) -> 104.24242 | D21: =(((1-(($C21-h_elipse)^2/a_elipse^2))*(b_elipse^2))^0.5)+k_elipse -> 69.949942 | E21: =E20+(D20-D21) -> 30.050058 | F21: =(F20-(C21-C20)) -> 95.757576 | G21: =D21 -> 69.949942 | H21: =E21 -> 30.050058
B22: 9 | C22: =IF((a_elipse/np_elipse)+C21>=h_elipse+a_elipse,h_elipse+a_elipse,(a_elipse/np_elipse)+C21) -> 104.84848 | D22: =(((1-(($C22-h_elipse)^2/a_elipse^2))*(b_elipse^2))^0.5)+k_elipse -> 69.934594 | E22: =E21+(D21-D22) -> 30.065406 | F22: =(F21-(C22-C21)) -> 95.151515 | G22: =D22 -> 69.934594 | H22: =E22 -> 30.065406
B23: 10 | C23: =IF((a_elipse/np_elipse)+C22>=h_elipse+a_elipse,h_elipse+a_elipse,(a_elipse/np_elipse)+C22) -> 105.45455 | D23: =(((1-(($C23-h_elipse)^2/a_elipse^2))*(b_elipse^2))^0.5)+k_elipse -> 69.917184 | E23: =E22+(D22-D23) -> 30.082816 | F23: =(F22-(C23-C22)) -> 94.545455 | G23: =D23 -> 69.917184 | H23: =E23 -> 30.082816
B24: 11 | C24: =IF((a_elipse/np_elipse)+C23>=h_elipse+a_elipse,h_elipse+a_elipse,(a_elipse/np_elipse)+C23) -> 106.06061 | D24: =(((1-(($C24-h_elipse)^2/a_elipse^2))*(b_elipse^2))^0.5)+k_elipse -> 69.897708 | E24: =E23+(D23-D24) -> 30.102292 | F24: =(F23-(C24-C23)) -> 93.939394 | G24: =D24 -> 69.897708 | H24: =E24 -> 30.102292
B25: 12 | C25: =IF((a_elipse/np_elipse)+C24>=h_elipse+a_elipse,h_elipse+a_elipse,(a_elipse/np_elipse)+C24) -> 106.66667 | D25: =(((1-(($C25-h_elipse)^2/a_elipse^2))*(b_elipse^2))^0.5)+k_elipse -> 69.87616 | E25: =E24+(D24-D25) -> 30.12384 | F25: =(F24-(C25-C24)) -> 93.333333 | G25: =D25 -> 69.87616 | H25: =E25 -> 30.12384
B26: 13 | C26: =IF((a_elipse/np_elipse)+C25>=h_elipse+a_elipse,h_elipse+a_elipse,(a_elipse/np_elipse)+C25) -> 107.27273 | D26: =(((1-(($C26-h_elipse)^2/a_elipse^2))*(b_elipse^2))^0.5)+k_elipse -> 69.852533 | E26: =E25+(D25-D26) -> 30.147467 | F26: =(F25-(C26-C25)) -> 92.727273 | G26: =D26 -> 69.852533 | H26: =E26 -> 30.147467
... B113: 100 | C113: =IF((a_elipse/np_elipse)+C112>=h_elipse+a_elipse,h_elipse+a_elipse,(a_elipse/np_elipse)+C112) -> 160 | D113: =(((1-(($C113-h_elipse)^2/a_elipse^2))*(b_elipse^2))^0.5)+k_elipse -> 50 | E113: =E112+(D112-D113) -> 50 | F113: =(F112-(C113-C112)) -> 40 | G113: =D113 -> 50 | H113: =E113 -> 50

Sheet ElipseAutoCAD
A1: PLINE
A2: =_xlfn.CONCAT(ElipseTabla!$C14,",",ElipseTabla!D14) -> 100,70 | B2: =_xlfn.CONCAT("POINT ",A2) -> POINT 100,70
A3: =_xlfn.CONCAT(ElipseTabla!C15,",",ElipseTabla!$D15) -> 100.606060606061,69.9989796699226 | B3: =_xlfn.CONCAT("POINT ",A3) -> POINT 100.606060606061,69.9989796699226
A4: =_xlfn.CONCAT(ElipseTabla!C16,",",ElipseTabla!D16) -> 101.212121212121,69.9959183673044 | B4: =_xlfn.CONCAT("POINT ",A4) -> POINT 101.212121212121,69.9959183673044
A5: =_xlfn.CONCAT(ElipseTabla!C17,",",ElipseTabla!D17) -> 101.818181818182,69.9908151545099 | B5: =_xlfn.CONCAT("POINT ",A5) -> POINT 101.818181818182,69.9908151545099
A6: =_xlfn.CONCAT(ElipseTabla!C18,",",ElipseTabla!D18) -> 102.424242424242,69.9836684672162 | B6: =_xlfn.CONCAT("POINT ",A6) -> POINT 102.424242424242,69.9836684672162
A7: =_xlfn.CONCAT(ElipseTabla!C19,",",ElipseTabla!D19) -> 103.030303030303,69.9744761120134 | B7: =_xlfn.CONCAT("POINT ",A7) -> POINT 103.030303030303,69.9744761120134
A8: =_xlfn.CONCAT(ElipseTabla!C20,",",ElipseTabla!D20) -> 103.636363636364,69.963235263031 | B8: =_xlfn.CONCAT("POINT ",A8) -> POINT 103.636363636364,69.963235263031
A9: =_xlfn.CONCAT(ElipseTabla!C21,",",ElipseTabla!D21) -> 104.242424242424,69.9499424575814 | B9: =_xlfn.CONCAT("POINT ",A9) -> POINT 104.242424242424,69.9499424575814
A10: =_xlfn.CONCAT(ElipseTabla!C22,",",ElipseTabla!D22) -> 104.848484848485,69.934593590802 | B10: =_xlfn.CONCAT("POINT ",A10) -> POINT 104.848484848485,69.934593590802
A11: =_xlfn.CONCAT(ElipseTabla!C23,",",ElipseTabla!D23) -> 105.454545454545,69.9171839092788 | B11: =_xlfn.CONCAT("POINT ",A11) -> POINT 105.454545454545,69.9171839092788
A12: =_xlfn.CONCAT(ElipseTabla!C24,",",ElipseTabla!D24) -> 106.060606060606,69.8977080036262 | B12: =_xlfn.CONCAT("POINT ",A12) -> POINT 106.060606060606,69.8977080036262
A13: =_xlfn.CONCAT(ElipseTabla!C25,",",ElipseTabla!D25) -> 106.666666666667,69.8761597999981 | B13: =_xlfn.CONCAT("POINT ",A13) -> POINT 106.666666666667,69.8761597999981
A14: =_xlfn.CONCAT(ElipseTabla!C26,",",ElipseTabla!D26) -> 107.272727272727,69.852532550496 | B14: =_xlfn.CONCAT("POINT ",A14) -> POINT 107.272727272727,69.852532550496
A15: =_xlfn.CONCAT(ElipseTabla!C27,",",ElipseTabla!D27) -> 107.878787878788,69.8268188224409 | B15: =_xlfn.CONCAT("POINT ",A15) -> POINT 107.878787878788,69.8268188224409
... A101: =_xlfn.CONCAT(ElipseTabla!C113,",",ElipseTabla!D113) -> 160,50 | B101: =_xlfn.CONCAT("POINT ",A101) -> POINT 160,50
A103: PLINE
A104: =_xlfn.CONCAT(ElipseTabla!$C14,",",ElipseTabla!E14) -> 100,30 | B104: =_xlfn.CONCAT("POINT ",A104) -> POINT 100,30
A105: =_xlfn.CONCAT(ElipseTabla!$C15,",",ElipseTabla!E15) -> 100.606060606061,30.0010203300774 | B105: =_xlfn.CONCAT("POINT ",A105) -> POINT 100.606060606061,30.0010203300774
A106: =_xlfn.CONCAT(ElipseTabla!$C16,",",ElipseTabla!E16) -> 101.212121212121,30.0040816326956 | B106: =_xlfn.CONCAT("POINT ",A106) -> POINT 101.212121212121,30.0040816326956
A107: =_xlfn.CONCAT(ElipseTabla!$C17,",",ElipseTabla!E17) -> 101.818181818182,30.0091848454901 | B107: =_xlfn.CONCAT("POINT ",A107) -> POINT 101.818181818182,30.0091848454901
A108: =_xlfn.CONCAT(ElipseTabla!$C18,",",ElipseTabla!E18) -> 102.424242424242,30.0163315327838 | B108: =_xlfn.CONCAT("POINT ",A108) -> POINT 102.424242424242,30.0163315327838
A109: =_xlfn.CONCAT(ElipseTabla!$C19,",",ElipseTabla!E19) -> 103.030303030303,30.0255238879866 | B109: =_xlfn.CONCAT("POINT ",A109) -> POINT 103.030303030303,30.0255238879866
A110: =_xlfn.CONCAT(ElipseTabla!$C20,",",ElipseTabla!E20) -> 103.636363636364,30.036764736969 | B110: =_xlfn.CONCAT("POINT ",A110) -> POINT 103.636363636364,30.036764736969
A111: =_xlfn.CONCAT(ElipseTabla!$C21,",",ElipseTabla!E21) -> 104.242424242424,30.0500575424186 | B111: =_xlfn.CONCAT("POINT ",A111) -> POINT 104.242424242424,30.0500575424186
A112: =_xlfn.CONCAT(ElipseTabla!$C22,",",ElipseTabla!E22) -> 104.848484848485,30.065406409198 | B112: =_xlfn.CONCAT("POINT ",A112) -> POINT 104.848484848485,30.065406409198
A113: =_xlfn.CONCAT(ElipseTabla!$C23,",",ElipseTabla!E23) -> 105.454545454545,30.0828160907212 | B113: =_xlfn.CONCAT("POINT ",A113) -> POINT 105.454545454545,30.0828160907212
A114: =_xlfn.CONCAT(ElipseTabla!$C24,",",ElipseTabla!E24) -> 106.060606060606,30.1022919963738 | B114: =_xlfn.CONCAT("POINT ",A114) -> POINT 106.060606060606,30.1022919963738
A115: =_xlfn.CONCAT(ElipseTabla!$C25,",",ElipseTabla!E25) -> 106.666666666667,30.1238402000019 | B115: =_xlfn.CONCAT("POINT ",A115) -> POINT 106.666666666667,30.1238402000019
... A203: =_xlfn.CONCAT(ElipseTabla!$C113,",",ElipseTabla!E113) -> 160,50 | B203: =_xlfn.CONCAT("POINT ",A203) -> POINT 160,50
A205: PLINE
A206: =_xlfn.CONCAT(ElipseTabla!$F14,",",ElipseTabla!G14) -> 100,70 | B206: =_xlfn.CONCAT("POINT ",A206) -> POINT 100,70
A207: =_xlfn.CONCAT(ElipseTabla!$F15,",",ElipseTabla!G15) -> 99.3939393939394,69.9989796699226 | B207: =_xlfn.CONCAT("POINT ",A207) -> POINT 99.3939393939394,69.9989796699226
A208: =_xlfn.CONCAT(ElipseTabla!$F16,",",ElipseTabla!G16) -> 98.7878787878788,69.9959183673044 | B208: =_xlfn.CONCAT("POINT ",A208) -> POINT 98.7878787878788,69.9959183673044
A209: =_xlfn.CONCAT(ElipseTabla!$F17,",",ElipseTabla!G17) -> 98.1818181818182,69.9908151545099 | B209: =_xlfn.CONCAT("POINT ",A209) -> POINT 98.1818181818182,69.9908151545099
A210: =_xlfn.CONCAT(ElipseTabla!$F18,",",ElipseTabla!G18) -> 97.5757575757576,69.9836684672162 | B210: =_xlfn.CONCAT("POINT ",A210) -> POINT 97.5757575757576,69.9836684672162
A211: =_xlfn.CONCAT(ElipseTabla!$F19,",",ElipseTabla!G19) -> 96.969696969697,69.9744761120134 | B211: =_xlfn.CONCAT("POINT ",A211) -> POINT 96.969696969697,69.9744761120134
A212: =_xlfn.CONCAT(ElipseTabla!$F20,",",ElipseTabla!G20) -> 96.3636363636363,69.963235263031 | B212: =_xlfn.CONCAT("POINT ",A212) -> POINT 96.3636363636363,69.963235263031
A213: =_xlfn.CONCAT(ElipseTabla!$F21,",",ElipseTabla!G21) -> 95.7575757575757,69.9499424575814 | B213: =_xlfn.CONCAT("POINT ",A213) -> POINT 95.7575757575757,69.9499424575814
A214: =_xlfn.CONCAT(ElipseTabla!$F22,",",ElipseTabla!G22) -> 95.1515151515151,69.934593590802 | B214: =_xlfn.CONCAT("POINT ",A214) -> POINT 95.1515151515151,69.934593590802
...

Sheet SuperElipseTabla
H1: v.20260206
B3: Dibujo de Superelipse con centro en el orígen
B5: Parámetro | D5: Valor
B6: Factor de forma n | D6: 4
B7: Semieje mayor, a | D7: 105
B8: Semieje menor, b | D8: 68
B9: Puntos por cuadrante | D9: 99
B10: Nodo | C10: X | D10: YC1 | E10: YC2 | F10: -X | G10: YC3 | H10: YC4
B11: 1 | C11: 0 | D11: =((1-($C11/a_superelipse)^n_superelipse)^(1/n_superelipse))*b_superelipse -> 68 | E11: =-D11 -> -68 | F11: =C11 -> 0 | G11: =D11 -> 68 | H11: =E11 -> -68
B12: 2 | C12: =IF((a_superelipse/np_superelipse)+C11>=a_superelipse,a_superelipse,(a_superelipse/np_superelipse)+C11) -> 1.0606061 | D12: =((1-($C12/a_superelipse)^n_superelipse)^(1/n_superelipse))*b_superelipse -> 68 | E12: =-D12 -> -68 | F12: =(F11-(C12-C11)) -> -1.0606061 | G12: =D12 -> 68 | H12: =E12 -> -68
B13: 3 | C13: =IF((a_superelipse/np_superelipse)+C12>=a_superelipse,a_superelipse,(a_superelipse/np_superelipse)+C12) -> 2.1212121 | D13: =((1-($C13/a_superelipse)^n_superelipse)^(1/n_superelipse))*b_superelipse -> 67.999997 | E13: =-D13 -> -67.999997 | F13: =(F12-(C13-C12)) -> -2.1212121 | G13: =D13 -> 67.999997 | H13: =E13 -> -67.999997
B14: 4 | C14: =IF((a_superelipse/np_superelipse)+C13>=a_superelipse,a_superelipse,(a_superelipse/np_superelipse)+C13) -> 3.1818182 | D14: =((1-($C14/a_superelipse)^n_superelipse)^(1/n_superelipse))*b_superelipse -> 67.999986 | E14: =-D14 -> -67.999986 | F14: =(F13-(C14-C13)) -> -3.1818182 | G14: =D14 -> 67.999986 | H14: =E14 -> -67.999986
B15: 5 | C15: =IF((a_superelipse/np_superelipse)+C14>=a_superelipse,a_superelipse,(a_superelipse/np_superelipse)+C14) -> 4.2424242 | D15: =((1-($C15/a_superelipse)^n_superelipse)^(1/n_superelipse))*b_superelipse -> 67.999955 | E15: =-D15 -> -67.999955 | F15: =(F14-(C15-C14)) -> -4.2424242 | G15: =D15 -> 67.999955 | H15: =E15 -> -67.999955
B16: 6 | C16: =IF((a_superelipse/np_superelipse)+C15>=a_superelipse,a_superelipse,(a_superelipse/np_superelipse)+C15) -> 5.3030303 | D16: =((1-($C16/a_superelipse)^n_superelipse)^(1/n_superelipse))*b_superelipse -> 67.999889 | E16: =-D16 -> -67.999889 | F16: =(F15-(C16-C15)) -> -5.3030303 | G16: =D16 -> 67.999889 | H16: =E16 -> -67.999889
B17: 7 | C17: =IF((a_superelipse/np_superelipse)+C16>=a_superelipse,a_superelipse,(a_superelipse/np_superelipse)+C16) -> 6.3636364 | D17: =((1-($C17/a_superelipse)^n_superelipse)^(1/n_superelipse))*b_superelipse -> 67.999771 | E17: =-D17 -> -67.999771 | F17: =(F16-(C17-C16)) -> -6.3636364 | G17: =D17 -> 67.999771 | H17: =E17 -> -67.999771
B18: 8 | C18: =IF((a_superelipse/np_superelipse)+C17>=a_superelipse,a_superelipse,(a_superelipse/np_superelipse)+C17) -> 7.4242424 | D18: =((1-($C18/a_superelipse)^n_superelipse)^(1/n_superelipse))*b_superelipse -> 67.999575 | E18: =-D18 -> -67.999575 | F18: =(F17-(C18-C17)) -> -7.4242424 | G18: =D18 -> 67.999575 | H18: =E18 -> -67.999575
B19: 9 | C19: =IF((a_superelipse/np_superelipse)+C18>=a_superelipse,a_superelipse,(a_superelipse/np_superelipse)+C18) -> 8.4848485 | D19: =((1-($C19/a_superelipse)^n_superelipse)^(1/n_superelipse))*b_superelipse -> 67.999275 | E19: =-D19 -> -67.999275 | F19: =(F18-(C19-C18)) -> -8.4848485 | G19: =D19 -> 67.999275 | H19: =E19 -> -67.999275
B20: 10 | C20: =IF((a_superelipse/np_superelipse)+C19>=a_superelipse,a_superelipse,(a_superelipse/np_superelipse)+C19) -> 9.5454545 | D20: =((1-($C20/a_superelipse)^n_superelipse)^(1/n_superelipse))*b_superelipse -> 67.998839 | E20: =-D20 -> -67.998839 | F20: =(F19-(C20-C19)) -> -9.5454545 | G20: =D20 -> 67.998839 | H20: =E20 -> -67.998839
B21: 11 | C21: =IF((a_superelipse/np_superelipse)+C20>=a_superelipse,a_superelipse,(a_superelipse/np_superelipse)+C20) -> 10.606061 | D21: =((1-($C21/a_superelipse)^n_superelipse)^(1/n_superelipse))*b_superelipse -> 67.99823 | E21: =-D21 -> -67.99823 | F21: =(F20-(C21-C20)) -> -10.606061 | G21: =D21 -> 67.99823 | H21: =E21 -> -67.99823
B22: 12 | C22: =IF((a_superelipse/np_superelipse)+C21>=a_superelipse,a_superelipse,(a_superelipse/np_superelipse)+C21) -> 11.666667 | D22: =((1-($C22/a_superelipse)^n_superelipse)^(1/n_superelipse))*b_superelipse -> 67.997409 | E22: =-D22 -> -67.997409 | F22: =(F21-(C22-C21)) -> -11.666667 | G22: =D22 -> 67.997409 | H22: =E22 -> -67.997409
B23: 13 | C23: =IF((a_superelipse/np_superelipse)+C22>=a_superelipse,a_superelipse,(a_superelipse/np_superelipse)+C22) -> 12.727273 | D23: =((1-($C23/a_superelipse)^n_superelipse)^(1/n_superelipse))*b_superelipse -> 67.99633 | E23: =-D23 -> -67.99633 | F23: =(F22-(C23-C22)) -> -12.727273 | G23: =D23 -> 67.99633 | H23: =E23 -> -67.99633
... B110: 100 | C110: =IF((a_superelipse/np_superelipse)+C109>=a_superelipse,a_superelipse,(a_superelipse/np_superelipse)+C109) -> 105 | D110: =((1-($C110/a_superelipse)^n_superelipse)^(1/n_superelipse))*b_superelipse -> 0 | E110: =-D110 -> 0 | F110: =(F109-(C110-C109)) -> -105 | G110: =D110 -> 0 | H110: =E110 -> 0

Sheet SuperElipseAutoCAD
A1: PLINE
A2: =_xlfn.CONCAT(SuperElipseTabla!$C11,",",SuperElipseTabla!D11) -> 0,68 | B2: =_xlfn.CONCAT("POINT ",A2) -> POINT 0,68
A3: =_xlfn.CONCAT(SuperElipseTabla!C12,",",SuperElipseTabla!$D12) -> 1.06060606060606,67.9999998230265 | B3: =_xlfn.CONCAT("POINT ",A3) -> POINT 1.06060606060606,67.9999998230265
A4: =_xlfn.CONCAT(SuperElipseTabla!C13,",",SuperElipseTabla!D13) -> 2.12121212121212,67.9999971684245 | B4: =_xlfn.CONCAT("POINT ",A4) -> POINT 2.12121212121212,67.9999971684245
A5: =_xlfn.CONCAT(SuperElipseTabla!C14,",",SuperElipseTabla!D14) -> 3.18181818181818,67.9999856651452 | B5: =_xlfn.CONCAT("POINT ",A5) -> POINT 3.18181818181818,67.9999856651452
A6: =_xlfn.CONCAT(SuperElipseTabla!C15,",",SuperElipseTabla!D15) -> 4.24242424242424,67.9999546947489 | B6: =_xlfn.CONCAT("POINT ",A6) -> POINT 4.24242424242424,67.9999546947489
A7: =_xlfn.CONCAT(SuperElipseTabla!C16,",",SuperElipseTabla!D16) -> 5.3030303030303,67.9998893913173 | B7: =_xlfn.CONCAT("POINT ",A7) -> POINT 5.3030303030303,67.9998893913173
A8: =_xlfn.CONCAT(SuperElipseTabla!C17,",",SuperElipseTabla!D17) -> 6.36363636363636,67.9997706412348 | B8: =_xlfn.CONCAT("POINT ",A8) -> POINT 6.36363636363636,67.9997706412348
A9: =_xlfn.CONCAT(SuperElipseTabla!C18,",",SuperElipseTabla!D18) -> 7.42424242424242,67.9995750827386 | B9: =_xlfn.CONCAT("POINT ",A9) -> POINT 7.42424242424242,67.9995750827386
A10: =_xlfn.CONCAT(SuperElipseTabla!C19,",",SuperElipseTabla!D19) -> 8.48484848484848,67.9992751051147 | B10: =_xlfn.CONCAT("POINT ",A10) -> POINT 8.48484848484848,67.9992751051147
A11: =_xlfn.CONCAT(SuperElipseTabla!C20,",",SuperElipseTabla!D20) -> 9.54545454545454,67.9988388473848 | B11: =_xlfn.CONCAT("POINT ",A11) -> POINT 9.54545454545454,67.9988388473848
A12: =_xlfn.CONCAT(SuperElipseTabla!C21,",",SuperElipseTabla!D21) -> 10.6060606060606,67.9982301963038 | B12: =_xlfn.CONCAT("POINT ",A12) -> POINT 10.6060606060606,67.9982301963038
A13: =_xlfn.CONCAT(SuperElipseTabla!C22,",",SuperElipseTabla!D22) -> 11.6666666666667,67.9974087834572 | B13: =_xlfn.CONCAT("POINT ",A13) -> POINT 11.6666666666667,67.9974087834572
A14: =_xlfn.CONCAT(SuperElipseTabla!C23,",",SuperElipseTabla!D23) -> 12.7272727272727,67.9963299812233 | B14: =_xlfn.CONCAT("POINT ",A14) -> POINT 12.7272727272727,67.9963299812233
A15: =_xlfn.CONCAT(SuperElipseTabla!C24,",",SuperElipseTabla!D24) -> 13.7878787878788,67.994944897331 | B15: =_xlfn.CONCAT("POINT ",A15) -> POINT 13.7878787878788,67.994944897331
... A101: =_xlfn.CONCAT(SuperElipseTabla!C110,",",SuperElipseTabla!D110) -> 105,0 | B101: =_xlfn.CONCAT("POINT ",A101) -> POINT 105,0
A103: PLINE
A104: =_xlfn.CONCAT(SuperElipseTabla!$C11,",",SuperElipseTabla!E11) -> 0,-68 | B104: =_xlfn.CONCAT("POINT ",A104) -> POINT 0,-68
A105: =_xlfn.CONCAT(SuperElipseTabla!$C12,",",SuperElipseTabla!E12) -> 1.06060606060606,-67.9999998230265 | B105: =_xlfn.CONCAT("POINT ",A105) -> POINT 1.06060606060606,-67.9999998230265
A106: =_xlfn.CONCAT(SuperElipseTabla!$C13,",",SuperElipseTabla!E13) -> 2.12121212121212,-67.9999971684245 | B106: =_xlfn.CONCAT("POINT ",A106) -> POINT 2.12121212121212,-67.9999971684245
A107: =_xlfn.CONCAT(SuperElipseTabla!$C14,",",SuperElipseTabla!E14) -> 3.18181818181818,-67.9999856651452 | B107: =_xlfn.CONCAT("POINT ",A107) -> POINT 3.18181818181818,-67.9999856651452
A108: =_xlfn.CONCAT(SuperElipseTabla!$C15,",",SuperElipseTabla!E15) -> 4.24242424242424,-67.9999546947489 | B108: =_xlfn.CONCAT("POINT ",A108) -> POINT 4.24242424242424,-67.9999546947489
A109: =_xlfn.CONCAT(SuperElipseTabla!$C16,",",SuperElipseTabla!E16) -> 5.3030303030303,-67.9998893913173 | B109: =_xlfn.CONCAT("POINT ",A109) -> POINT 5.3030303030303,-67.9998893913173
A110: =_xlfn.CONCAT(SuperElipseTabla!$C17,",",SuperElipseTabla!E17) -> 6.36363636363636,-67.9997706412348 | B110: =_xlfn.CONCAT("POINT ",A110) -> POINT 6.36363636363636,-67.9997706412348
A111: =_xlfn.CONCAT(SuperElipseTabla!$C18,",",SuperElipseTabla!E18) -> 7.42424242424242,-67.9995750827386 | B111: =_xlfn.CONCAT("POINT ",A111) -> POINT 7.42424242424242,-67.9995750827386
A112: =_xlfn.CONCAT(SuperElipseTabla!$C19,",",SuperElipseTabla!E19) -> 8.48484848484848,-67.9992751051147 | B112: =_xlfn.CONCAT("POINT ",A112) -> POINT 8.48484848484848,-67.9992751051147
A113: =_xlfn.CONCAT(SuperElipseTabla!$C20,",",SuperElipseTabla!E20) -> 9.54545454545454,-67.9988388473848 | B113: =_xlfn.CONCAT("POINT ",A113) -> POINT 9.54545454545454,-67.9988388473848
A114: =_xlfn.CONCAT(SuperElipseTabla!$C21,",",SuperElipseTabla!E21) -> 10.6060606060606,-67.9982301963038 | B114: =_xlfn.CONCAT("POINT ",A114) -> POINT 10.6060606060606,-67.9982301963038
A115: =_xlfn.CONCAT(SuperElipseTabla!$C22,",",SuperElipseTabla!E22) -> 11.6666666666667,-67.9974087834572 | B115: =_xlfn.CONCAT("POINT ",A115) -> POINT 11.6666666666667,-67.9974087834572
... A203: =_xlfn.CONCAT(SuperElipseTabla!$C110,",",SuperElipseTabla!E110) -> 105,0 | B203: =_xlfn.CONCAT("POINT ",A203) -> POINT 105,0
A205: PLINE
A206: =_xlfn.CONCAT(SuperElipseTabla!$F11,",",SuperElipseTabla!G11) -> 0,68 | B206: =_xlfn.CONCAT("POINT ",A206) -> POINT 0,68
A207: =_xlfn.CONCAT(SuperElipseTabla!$F12,",",SuperElipseTabla!G12) -> -1.06060606060606,67.9999998230265 | B207: =_xlfn.CONCAT("POINT ",A207) -> POINT -1.06060606060606,67.9999998230265
A208: =_xlfn.CONCAT(SuperElipseTabla!$F13,",",SuperElipseTabla!G13) -> -2.12121212121212,67.9999971684245 | B208: =_xlfn.CONCAT("POINT ",A208) -> POINT -2.12121212121212,67.9999971684245
A209: =_xlfn.CONCAT(SuperElipseTabla!$F14,",",SuperElipseTabla!G14) -> -3.18181818181818,67.9999856651452 | B209: =_xlfn.CONCAT("POINT ",A209) -> POINT -3.18181818181818,67.9999856651452
A210: =_xlfn.CONCAT(SuperElipseTabla!$F15,",",SuperElipseTabla!G15) -> -4.24242424242424,67.9999546947489 | B210: =_xlfn.CONCAT("POINT ",A210) -> POINT -4.24242424242424,67.9999546947489
A211: =_xlfn.CONCAT(SuperElipseTabla!$F16,",",SuperElipseTabla!G16) -> -5.3030303030303,67.9998893913173 | B211: =_xlfn.CONCAT("POINT ",A211) -> POINT -5.3030303030303,67.9998893913173
A212: =_xlfn.CONCAT(SuperElipseTabla!$F17,",",SuperElipseTabla!G17) -> -6.36363636363636,67.9997706412348 | B212: =_xlfn.CONCAT("POINT ",A212) -> POINT -6.36363636363636,67.9997706412348
A213: =_xlfn.CONCAT(SuperElipseTabla!$F18,",",SuperElipseTabla!G18) -> -7.42424242424242,67.9995750827386 | B213: =_xlfn.CONCAT("POINT ",A213) -> POINT -7.42424242424242,67.9995750827386
A214: =_xlfn.CONCAT(SuperElipseTabla!$F19,",",SuperElipseTabla!G19) -> -8.48484848484848,67.9992751051147 | B214: =_xlfn.CONCAT("POINT ",A214) -> POINT -8.48484848484848,67.9992751051147
...

Sheet HiperbolaTabla
F1: v.20250701
B3: Dibujo de la parábola con centro en origen (0,0)
B5: Parámetro | D5: Valor
B6: Inicio en x | D6: -30
B7: Fin en x | D7: =ABS(xstart_hiperbola) -> 30
B8: a | D8: 12
B9: b | D9: 9
B10: Puntos por cuadrante | D10: 100
B13: Nodo | C13: X | D13: Ysup | E13: -X | F13: Yinf
B14: 1 | C14: =xstart_hiperbola -> -30 | D14: =IFERROR(((($C14^2/a_hiperbola^2)-1)*b_hiperbola^2)^0.5,"") -> 20.621591 | E14: =-C14 -> 30 | F14: =IFERROR(-D14,"") -> -20.621591
B15: 2 | C15: =IF(C14-(xstart_hiperbola-xend_hiperbola)/np_hiperbola>xend_hiperbola,xend_hiperbola,C14-(xstart_hiperbola-xend_hiperbola)/np_hiperbola) -> -29.4 | D15: =IFERROR(((($C15^2/a_hiperbola^2)-1)*b_hiperbola^2)^0.5,"") -> 20.129642 | E15: =-C15 -> 29.4 | F15: =IFERROR(-D15,"") -> -20.129642
B16: 3 | C16: =IF(C15-(xstart_hiperbola-xend_hiperbola)/np_hiperbola>xend_hiperbola,xend_hiperbola,C15-(xstart_hiperbola-xend_hiperbola)/np_hiperbola) -> -28.8 | D16: =IFERROR(((($C16^2/a_hiperbola^2)-1)*b_hiperbola^2)^0.5,"") -> 19.635682 | E16: =-C16 -> 28.8 | F16: =IFERROR(-D16,"") -> -19.635682
B17: 4 | C17: =IF(C16-(xstart_hiperbola-xend_hiperbola)/np_hiperbola>xend_hiperbola,xend_hiperbola,C16-(xstart_hiperbola-xend_hiperbola)/np_hiperbola) -> -28.2 | D17: =IFERROR(((($C17^2/a_hiperbola^2)-1)*b_hiperbola^2)^0.5,"") -> 19.139553 | E17: =-C17 -> 28.2 | F17: =IFERROR(-D17,"") -> -19.139553
B18: 5 | C18: =IF(C17-(xstart_hiperbola-xend_hiperbola)/np_hiperbola>xend_hiperbola,xend_hiperbola,C17-(xstart_hiperbola-xend_hiperbola)/np_hiperbola) -> -27.6 | D18: =IFERROR(((($C18^2/a_hiperbola^2)-1)*b_hiperbola^2)^0.5,"") -> 18.641084 | E18: =-C18 -> 27.6 | F18: =IFERROR(-D18,"") -> -18.641084
B19: 6 | C19: =IF(C18-(xstart_hiperbola-xend_hiperbola)/np_hiperbola>xend_hiperbola,xend_hiperbola,C18-(xstart_hiperbola-xend_hiperbola)/np_hiperbola) -> -27 | D19: =IFERROR(((($C19^2/a_hiperbola^2)-1)*b_hiperbola^2)^0.5,"") -> 18.14008 | E19: =-C19 -> 27 | F19: =IFERROR(-D19,"") -> -18.14008
B20: 7 | C20: =IF(C19-(xstart_hiperbola-xend_hiperbola)/np_hiperbola>xend_hiperbola,xend_hiperbola,C19-(xstart_hiperbola-xend_hiperbola)/np_hiperbola) -> -26.4 | D20: =IFERROR(((($C20^2/a_hiperbola^2)-1)*b_hiperbola^2)^0.5,"") -> 17.636326 | E20: =-C20 -> 26.4 | F20: =IFERROR(-D20,"") -> -17.636326
B21: 8 | C21: =IF(C20-(xstart_hiperbola-xend_hiperbola)/np_hiperbola>xend_hiperbola,xend_hiperbola,C20-(xstart_hiperbola-xend_hiperbola)/np_hiperbola) -> -25.8 | D21: =IFERROR(((($C21^2/a_hiperbola^2)-1)*b_hiperbola^2)^0.5,"") -> 17.12958 | E21: =-C21 -> 25.8 | F21: =IFERROR(-D21,"") -> -17.12958
B22: 9 | C22: =IF(C21-(xstart_hiperbola-xend_hiperbola)/np_hiperbola>xend_hiperbola,xend_hiperbola,C21-(xstart_hiperbola-xend_hiperbola)/np_hiperbola) -> -25.2 | D22: =IFERROR(((($C22^2/a_hiperbola^2)-1)*b_hiperbola^2)^0.5,"") -> 16.619567 | E22: =-C22 -> 25.2 | F22: =IFERROR(-D22,"") -> -16.619567
B23: 10 | C23: =IF(C22-(xstart_hiperbola-xend_hiperbola)/np_hiperbola>xend_hiperbola,xend_hiperbola,C22-(xstart_hiperbola-xend_hiperbola)/np_hiperbola) -> -24.6 | D23: =IFERROR(((($C23^2/a_hiperbola^2)-1)*b_hiperbola^2)^0.5,"") -> 16.105977 | E23: =-C23 -> 24.6 | F23: =IFERROR(-D23,"") -> -16.105977
B24: 11 | C24: =IF(C23-(xstart_hiperbola-xend_hiperbola)/np_hiperbola>xend_hiperbola,xend_hiperbola,C23-(xstart_hiperbola-xend_hiperbola)/np_hiperbola) -> -24 | D24: =IFERROR(((($C24^2/a_hiperbola^2)-1)*b_hiperbola^2)^0.5,"") -> 15.588457 | E24: =-C24 -> 24 | F24: =IFERROR(-D24,"") -> -15.588457
B25: 12 | C25: =IF(C24-(xstart_hiperbola-xend_hiperbola)/np_hiperbola>xend_hiperbola,xend_hiperbola,C24-(xstart_hiperbola-xend_hiperbola)/np_hiperbola) -> -23.4 | D25: =IFERROR(((($C25^2/a_hiperbola^2)-1)*b_hiperbola^2)^0.5,"") -> 15.066602 | E25: =-C25 -> 23.4 | F25: =IFERROR(-D25,"") -> -15.066602
B26: 13 | C26: =IF(C25-(xstart_hiperbola-xend_hiperbola)/np_hiperbola>xend_hiperbola,xend_hiperbola,C25-(xstart_hiperbola-xend_hiperbola)/np_hiperbola) -> -22.8 | D26: =IFERROR(((($C26^2/a_hiperbola^2)-1)*b_hiperbola^2)^0.5,"") -> 14.539945 | E26: =-C26 -> 22.8 | F26: =IFERROR(-D26,"") -> -14.539945
... B113: 100 | C113: =IF(C112-(xstart_hiperbola-xend_hiperbola)/np_hiperbola>xend_hiperbola,xend_hiperbola,C112-(xstart_hiperbola-xend_hiperbola)/np_hiperbola) -> 29.4 | D113: =IFERROR(((($C113^2/a_hiperbola^2)-1)*b_hiperbola^2)^0.5,"") -> 20.129642 | E113: =-C113 -> -29.4 | F113: =IFERROR(-D113,"") -> -20.129642

Sheet HiperbolaAutoCAD
A1: PLINE
A2: =_xlfn.CONCAT(HiperbolaTabla!$C14,",",HiperbolaTabla!D14) -> -30,20.6215906273013 | B2: =_xlfn.CONCAT("POINT ",A2) -> POINT -30,20.6215906273013
A3: =_xlfn.CONCAT(HiperbolaTabla!$C15,",",HiperbolaTabla!D15) -> -29.4,20.1296423217105 | B3: =_xlfn.CONCAT("POINT ",A3) -> POINT -29.4,20.1296423217105
A4: =_xlfn.CONCAT(HiperbolaTabla!$C16,",",HiperbolaTabla!D16) -> -28.8,19.6356818063443 | B4: =_xlfn.CONCAT("POINT ",A4) -> POINT -28.8,19.6356818063443
A5: =_xlfn.CONCAT(HiperbolaTabla!$C17,",",HiperbolaTabla!D17) -> -28.2,19.1395532863231 | B5: =_xlfn.CONCAT("POINT ",A5) -> POINT -28.2,19.1395532863231
A6: =_xlfn.CONCAT(HiperbolaTabla!$C18,",",HiperbolaTabla!D18) -> -27.6,18.6410836594872 | B6: =_xlfn.CONCAT("POINT ",A6) -> POINT -27.6,18.6410836594872
A7: =_xlfn.CONCAT(HiperbolaTabla!$C19,",",HiperbolaTabla!D19) -> -27,18.1400799336717 | B7: =_xlfn.CONCAT("POINT ",A7) -> POINT -27,18.1400799336717
A8: =_xlfn.CONCAT(HiperbolaTabla!$C20,",",HiperbolaTabla!D20) -> -26.4,17.6363261480389 | B8: =_xlfn.CONCAT("POINT ",A8) -> POINT -26.4,17.6363261480389
A9: =_xlfn.CONCAT(HiperbolaTabla!$C21,",",HiperbolaTabla!D21) -> -25.8,17.1295796796068 | B9: =_xlfn.CONCAT("POINT ",A9) -> POINT -25.8,17.1295796796068
A10: =_xlfn.CONCAT(HiperbolaTabla!$C22,",",HiperbolaTabla!D22) -> -25.2,16.6195667813574 | B10: =_xlfn.CONCAT("POINT ",A10) -> POINT -25.2,16.6195667813574
A11: =_xlfn.CONCAT(HiperbolaTabla!$C23,",",HiperbolaTabla!D23) -> -24.6,16.1059771513559 | B11: =_xlfn.CONCAT("POINT ",A11) -> POINT -24.6,16.1059771513559
A12: =_xlfn.CONCAT(HiperbolaTabla!$C24,",",HiperbolaTabla!D24) -> -24,15.5884572681199 | B12: =_xlfn.CONCAT("POINT ",A12) -> POINT -24,15.5884572681199
A13: =_xlfn.CONCAT(HiperbolaTabla!$C25,",",HiperbolaTabla!D25) -> -23.4,15.0666021385049 | B13: =_xlfn.CONCAT("POINT ",A13) -> POINT -23.4,15.0666021385049
... A101: =_xlfn.CONCAT(HiperbolaTabla!$C113,",",HiperbolaTabla!D113) -> 29.4000000000001,20.1296423217106 | B101: =_xlfn.CONCAT("POINT ",A101) -> POINT 29.4000000000001,20.1296423217106
A103: PLINE
A104: =_xlfn.CONCAT(HiperbolaTabla!$E14,",",HiperbolaTabla!F14) -> 30,-20.6215906273013 | B104: =_xlfn.CONCAT("POINT ",A104) -> POINT 30,-20.6215906273013
A105: =_xlfn.CONCAT(HiperbolaTabla!$E15,",",HiperbolaTabla!F15) -> 29.4,-20.1296423217105 | B105: =_xlfn.CONCAT("POINT ",A105) -> POINT 29.4,-20.1296423217105
A106: =_xlfn.CONCAT(HiperbolaTabla!$E16,",",HiperbolaTabla!F16) -> 28.8,-19.6356818063443 | B106: =_xlfn.CONCAT("POINT ",A106) -> POINT 28.8,-19.6356818063443
A107: =_xlfn.CONCAT(HiperbolaTabla!$E17,",",HiperbolaTabla!F17) -> 28.2,-19.1395532863231 | B107: =_xlfn.CONCAT("POINT ",A107) -> POINT 28.2,-19.1395532863231
A108: =_xlfn.CONCAT(HiperbolaTabla!$E18,",",HiperbolaTabla!F18) -> 27.6,-18.6410836594872 | B108: =_xlfn.CONCAT("POINT ",A108) -> POINT 27.6,-18.6410836594872
A109: =_xlfn.CONCAT(HiperbolaTabla!$E19,",",HiperbolaTabla!F19) -> 27,-18.1400799336717 | B109: =_xlfn.CONCAT("POINT ",A109) -> POINT 27,-18.1400799336717
A110: =_xlfn.CONCAT(HiperbolaTabla!$E20,",",HiperbolaTabla!F20) -> 26.4,-17.6363261480389 | B110: =_xlfn.CONCAT("POINT ",A110) -> POINT 26.4,-17.6363261480389
A111: =_xlfn.CONCAT(HiperbolaTabla!$E21,",",HiperbolaTabla!F21) -> 25.8,-17.1295796796068 | B111: =_xlfn.CONCAT("POINT ",A111) -> POINT 25.8,-17.1295796796068
A112: =_xlfn.CONCAT(HiperbolaTabla!$E22,",",HiperbolaTabla!F22) -> 25.2,-16.6195667813574 | B112: =_xlfn.CONCAT("POINT ",A112) -> POINT 25.2,-16.6195667813574
A113: =_xlfn.CONCAT(HiperbolaTabla!$E23,",",HiperbolaTabla!F23) -> 24.6,-16.1059771513559 | B113: =_xlfn.CONCAT("POINT ",A113) -> POINT 24.6,-16.1059771513559
A114: =_xlfn.CONCAT(HiperbolaTabla!$E24,",",HiperbolaTabla!F24) -> 24,-15.5884572681199 | B114: =_xlfn.CONCAT("POINT ",A114) -> POINT 24,-15.5884572681199
A115: =_xlfn.CONCAT(HiperbolaTabla!$E25,",",HiperbolaTabla!F25) -> 23.4,-15.0666021385049 | B115: =_xlfn.CONCAT("POINT ",A115) -> POINT 23.4,-15.0666021385049
... A203: =_xlfn.CONCAT(HiperbolaTabla!$E113,",",HiperbolaTabla!F113) -> -29.4000000000001,-20.1296423217106 | B203: =_xlfn.CONCAT("POINT ",A203) -> POINT -29.4000000000001,-20.1296423217106

Sheet Trigonometrica
I1: v.20250701
B3: Funciones trigonométricas con orígen en (0,0) | H3: Límite y ±: | I3: 11
K16: AutoCAD Command
B17: x (grados) | C17: x (radianes) | D17: SIN(x) | E17: COS(x) | F17: TAN(x) | G17: COT(x) | H17: SEC(x) | I17: CSC(x) | K17: SIN(x) | L17: COS(x) | M17: TAN(x) | N17: COT(x) | O17: SEC(x) | P17: CSC(x)
B18: 0 | C18: =B18*PI()/180 -> 0 | D18: =IF(SIN(C18)>$I$3,$I$3,(IF(SIN(C18)<-$I$3,-$I$3,SIN(C18)))) -> 0 | E18: =IF(COS(C18)>$I$3,$I$3,(IF(COS(C18)<-$I$3,-$I$3,COS(C18)))) -> 1 | F18: =IF(TAN(C18)>$I$3,$I$3,(IF(TAN(C18)<-$I$3,-$I$3,TAN(C18)))) -> 0 | H18: =IF(_xlfn.SEC(C18)>$I$3,$I$3,(IF(_xlfn.SEC(C18)<-$I$3,-$I$3,_xlfn.SEC(C18)))) -> 1 | K18: SPLINE | L18: SPLINE | M18: PLINE | N18: PLINE | O18: PLINE | P18: PLINE
B19: 1 | C19: =B19*PI()/180 -> 0.017453293 | D19: =IF(SIN(C19)>$I$3,$I$3,(IF(SIN(C19)<-$I$3,-$I$3,SIN(C19)))) -> 0.017452406 | E19: =IF(COS(C19)>$I$3,$I$3,(IF(COS(C19)<-$I$3,-$I$3,COS(C19)))) -> 0.9998477 | F19: =IF(TAN(C19)>$I$3,$I$3,(IF(TAN(C19)<-$I$3,-$I$3,TAN(C19)))) -> 0.017455065 | G19: =IF(_xlfn.COT(C19)>$I$3,$I$3,(IF(_xlfn.COT(C19)<-$I$3,-$I$3,_xlfn.COT(C19)))) -> 11 | H19: =IF(_xlfn.SEC(C19)>$I$3,$I$3,(IF(_xlfn.SEC(C19)<-$I$3,-$I$3,_xlfn.SEC(C19)))) -> 1.0001523 | I19: =IF(_xlfn.CSC(C19)>$I$3,$I$3,(IF(_xlfn.CSC(C19)<-$I$3,-$I$3,_xlfn.CSC(C19)))) -> 11 | K19: =_xlfn.CONCAT($C18,",",D18) -> 0,0 | L19: =_xlfn.CONCAT($C18,",",E18) -> 0,1 | M19: =_xlfn.CONCAT($C18,",",F18) -> 0,0 | N19: =N20 -> 0.0174532925199433,11 | O19: =_xlfn.CONCAT($C18,",",H18) -> 0,1 | P19: =P20 -> 0.0174532925199433,11
B20: 2 | C20: =B20*PI()/180 -> 0.034906585 | D20: =IF(SIN(C20)>$I$3,$I$3,(IF(SIN(C20)<-$I$3,-$I$3,SIN(C20)))) -> 0.034899497 | E20: =IF(COS(C20)>$I$3,$I$3,(IF(COS(C20)<-$I$3,-$I$3,COS(C20)))) -> 0.99939083 | F20: =IF(TAN(C20)>$I$3,$I$3,(IF(TAN(C20)<-$I$3,-$I$3,TAN(C20)))) -> 0.034920769 | G20: =IF(_xlfn.COT(C20)>$I$3,$I$3,(IF(_xlfn.COT(C20)<-$I$3,-$I$3,_xlfn.COT(C20)))) -> 11 | H20: =IF(_xlfn.SEC(C20)>$I$3,$I$3,(IF(_xlfn.SEC(C20)<-$I$3,-$I$3,_xlfn.SEC(C20)))) -> 1.0006095 | I20: =IF(_xlfn.CSC(C20)>$I$3,$I$3,(IF(_xlfn.CSC(C20)<-$I$3,-$I$3,_xlfn.CSC(C20)))) -> 11 | K20: =_xlfn.CONCAT($C19,",",D19) -> 0.0174532925199433,0.0174524064372835 | L20: =_xlfn.CONCAT($C19,",",E19) -> 0.0174532925199433,0.999847695156391 | M20: =_xlfn.CONCAT($C19,",",F19) -> 0.0174532925199433,0.0174550649282176 | N20: =_xlfn.CONCAT($C19,",",G19) -> 0.0174532925199433,11 | O20: =_xlfn.CONCAT($C19,",",H19) -> 0.0174532925199433,1.00015232804391 | P20: =_xlfn.CONCAT($C19,",",I19) -> 0.0174532925199433,11
B21: 3 | C21: =B21*PI()/180 -> 0.052359878 | D21: =IF(SIN(C21)>$I$3,$I$3,(IF(SIN(C21)<-$I$3,-$I$3,SIN(C21)))) -> 0.052335956 | E21: =IF(COS(C21)>$I$3,$I$3,(IF(COS(C21)<-$I$3,-$I$3,COS(C21)))) -> 0.99862953 | F21: =IF(TAN(C21)>$I$3,$I$3,(IF(TAN(C21)<-$I$3,-$I$3,TAN(C21)))) -> 0.052407779 | G21: =IF(_xlfn.COT(C21)>$I$3,$I$3,(IF(_xlfn.COT(C21)<-$I$3,-$I$3,_xlfn.COT(C21)))) -> 11 | H21: =IF(_xlfn.SEC(C21)>$I$3,$I$3,(IF(_xlfn.SEC(C21)<-$I$3,-$I$3,_xlfn.SEC(C21)))) -> 1.0013723 | I21: =IF(_xlfn.CSC(C21)>$I$3,$I$3,(IF(_xlfn.CSC(C21)<-$I$3,-$I$3,_xlfn.CSC(C21)))) -> 11 | K21: =_xlfn.CONCAT($C20,",",D20) -> 0.0349065850398866,0.034899496702501 | L21: =_xlfn.CONCAT($C20,",",E20) -> 0.0349065850398866,0.999390827019096 | M21: =_xlfn.CONCAT($C20,",",F20) -> 0.0349065850398866,0.0349207694917477 | N21: =_xlfn.CONCAT($C20,",",G20) -> 0.0349065850398866,11 | O21: =_xlfn.CONCAT($C20,",",H20) -> 0.0349065850398866,1.00060954429882 | P21: =_xlfn.CONCAT($C20,",",I20) -> 0.0349065850398866,11
B22: 4 | C22: =B22*PI()/180 -> 0.06981317 | D22: =IF(SIN(C22)>$I$3,$I$3,(IF(SIN(C22)<-$I$3,-$I$3,SIN(C22)))) -> 0.069756474 | E22: =IF(COS(C22)>$I$3,$I$3,(IF(COS(C22)<-$I$3,-$I$3,COS(C22)))) -> 0.99756405 | F22: =IF(TAN(C22)>$I$3,$I$3,(IF(TAN(C22)<-$I$3,-$I$3,TAN(C22)))) -> 0.069926812 | G22: =IF(_xlfn.COT(C22)>$I$3,$I$3,(IF(_xlfn.COT(C22)<-$I$3,-$I$3,_xlfn.COT(C22)))) -> 11 | H22: =IF(_xlfn.SEC(C22)>$I$3,$I$3,(IF(_xlfn.SEC(C22)<-$I$3,-$I$3,_xlfn.SEC(C22)))) -> 1.0024419 | I22: =IF(_xlfn.CSC(C22)>$I$3,$I$3,(IF(_xlfn.CSC(C22)<-$I$3,-$I$3,_xlfn.CSC(C22)))) -> 11 | K22: =_xlfn.CONCAT($C21,",",D21) -> 0.0523598775598299,0.0523359562429438 | L22: =_xlfn.CONCAT($C21,",",E21) -> 0.0523598775598299,0.998629534754574 | M22: =_xlfn.CONCAT($C21,",",F21) -> 0.0523598775598299,0.0524077792830412 | N22: =_xlfn.CONCAT($C21,",",G21) -> 0.0523598775598299,11 | O22: =_xlfn.CONCAT($C21,",",H21) -> 0.0523598775598299,1.00137234599792 | P22: =_xlfn.CONCAT($C21,",",I21) -> 0.0523598775598299,11
B23: 5 | C23: =B23*PI()/180 -> 0.087266463 | D23: =IF(SIN(C23)>$I$3,$I$3,(IF(SIN(C23)<-$I$3,-$I$3,SIN(C23)))) -> 0.087155743 | E23: =IF(COS(C23)>$I$3,$I$3,(IF(COS(C23)<-$I$3,-$I$3,COS(C23)))) -> 0.9961947 | F23: =IF(TAN(C23)>$I$3,$I$3,(IF(TAN(C23)<-$I$3,-$I$3,TAN(C23)))) -> 0.087488664 | G23: =IF(_xlfn.COT(C23)>$I$3,$I$3,(IF(_xlfn.COT(C23)<-$I$3,-$I$3,_xlfn.COT(C23)))) -> 11 | H23: =IF(_xlfn.SEC(C23)>$I$3,$I$3,(IF(_xlfn.SEC(C23)<-$I$3,-$I$3,_xlfn.SEC(C23)))) -> 1.0038198 | I23: =IF(_xlfn.CSC(C23)>$I$3,$I$3,(IF(_xlfn.CSC(C23)<-$I$3,-$I$3,_xlfn.CSC(C23)))) -> 11 | K23: =_xlfn.CONCAT($C22,",",D22) -> 0.0698131700797732,0.0697564737441253 | L23: =_xlfn.CONCAT($C22,",",E22) -> 0.0698131700797732,0.997564050259824 | M23: =_xlfn.CONCAT($C22,",",F22) -> 0.0698131700797732,0.0699268119435104 | N23: =_xlfn.CONCAT($C22,",",G22) -> 0.0698131700797732,11 | O23: =_xlfn.CONCAT($C22,",",H22) -> 0.0698131700797732,1.00244189808117 | P23: =_xlfn.CONCAT($C22,",",I22) -> 0.0698131700797732,11
B24: 6 | C24: =B24*PI()/180 -> 0.10471976 | D24: =IF(SIN(C24)>$I$3,$I$3,(IF(SIN(C24)<-$I$3,-$I$3,SIN(C24)))) -> 0.10452846 | E24: =IF(COS(C24)>$I$3,$I$3,(IF(COS(C24)<-$I$3,-$I$3,COS(C24)))) -> 0.9945219 | F24: =IF(TAN(C24)>$I$3,$I$3,(IF(TAN(C24)<-$I$3,-$I$3,TAN(C24)))) -> 0.10510424 | G24: =IF(_xlfn.COT(C24)>$I$3,$I$3,(IF(_xlfn.COT(C24)<-$I$3,-$I$3,_xlfn.COT(C24)))) -> 9.5143645 | H24: =IF(_xlfn.SEC(C24)>$I$3,$I$3,(IF(_xlfn.SEC(C24)<-$I$3,-$I$3,_xlfn.SEC(C24)))) -> 1.0055083 | I24: =IF(_xlfn.CSC(C24)>$I$3,$I$3,(IF(_xlfn.CSC(C24)<-$I$3,-$I$3,_xlfn.CSC(C24)))) -> 9.5667722 | K24: =_xlfn.CONCAT($C23,",",D23) -> 0.0872664625997165,0.0871557427476582 | L24: =_xlfn.CONCAT($C23,",",E23) -> 0.0872664625997165,0.996194698091746 | M24: =_xlfn.CONCAT($C23,",",F23) -> 0.0872664625997165,0.087488663525924 | N24: =_xlfn.CONCAT($C23,",",G23) -> 0.0872664625997165,11 | O24: =_xlfn.CONCAT($C23,",",H23) -> 0.0872664625997165,1.00381983754335 | P24: =_xlfn.CONCAT($C23,",",I23) -> 0.0872664625997165,11
B25: 7 | C25: =B25*PI()/180 -> 0.12217305 | D25: =IF(SIN(C25)>$I$3,$I$3,(IF(SIN(C25)<-$I$3,-$I$3,SIN(C25)))) -> 0.12186934 | E25: =IF(COS(C25)>$I$3,$I$3,(IF(COS(C25)<-$I$3,-$I$3,COS(C25)))) -> 0.99254615 | F25: =IF(TAN(C25)>$I$3,$I$3,(IF(TAN(C25)<-$I$3,-$I$3,TAN(C25)))) -> 0.12278456 | G25: =IF(_xlfn.COT(C25)>$I$3,$I$3,(IF(_xlfn.COT(C25)<-$I$3,-$I$3,_xlfn.COT(C25)))) -> 8.1443464 | H25: =IF(_xlfn.SEC(C25)>$I$3,$I$3,(IF(_xlfn.SEC(C25)<-$I$3,-$I$3,_xlfn.SEC(C25)))) -> 1.0075098 | I25: =IF(_xlfn.CSC(C25)>$I$3,$I$3,(IF(_xlfn.CSC(C25)<-$I$3,-$I$3,_xlfn.CSC(C25)))) -> 8.205509 | K25: =_xlfn.CONCAT($C24,",",D24) -> 0.10471975511966,0.104528463267653 | L25: =_xlfn.CONCAT($C24,",",E24) -> 0.10471975511966,0.994521895368273 | M25: =_xlfn.CONCAT($C24,",",F24) -> 0.10471975511966,0.105104235265676 | N25: =_xlfn.CONCAT($C24,",",G24) -> 0.10471975511966,9.51436445422259 | O25: =_xlfn.CONCAT($C24,",",H24) -> 0.10471975511966,1.00550827956352 | P25: =_xlfn.CONCAT($C24,",",I24) -> 0.10471975511966,9.56677223350563
B26: 8 | C26: =B26*PI()/180 -> 0.13962634 | D26: =IF(SIN(C26)>$I$3,$I$3,(IF(SIN(C26)<-$I$3,-$I$3,SIN(C26)))) -> 0.1391731 | E26: =IF(COS(C26)>$I$3,$I$3,(IF(COS(C26)<-$I$3,-$I$3,COS(C26)))) -> 0.99026807 | F26: =IF(TAN(C26)>$I$3,$I$3,(IF(TAN(C26)<-$I$3,-$I$3,TAN(C26)))) -> 0.14054083 | G26: =IF(_xlfn.COT(C26)>$I$3,$I$3,(IF(_xlfn.COT(C26)<-$I$3,-$I$3,_xlfn.COT(C26)))) -> 7.1153697 | H26: =IF(_xlfn.SEC(C26)>$I$3,$I$3,(IF(_xlfn.SEC(C26)<-$I$3,-$I$3,_xlfn.SEC(C26)))) -> 1.0098276 | I26: =IF(_xlfn.CSC(C26)>$I$3,$I$3,(IF(_xlfn.CSC(C26)<-$I$3,-$I$3,_xlfn.CSC(C26)))) -> 7.1852965 | K26: =_xlfn.CONCAT($C25,",",D25) -> 0.122173047639603,0.121869343405147 | L26: =_xlfn.CONCAT($C25,",",E25) -> 0.122173047639603,0.992546151641322 | M26: =_xlfn.CONCAT($C25,",",F25) -> 0.122173047639603,0.122784560902905 | N26: =_xlfn.CONCAT($C25,",",G25) -> 0.122173047639603,8.14434642797459 | O26: =_xlfn.CONCAT($C25,",",H25) -> 0.122173047639603,1.00750982545885 | P26: =_xlfn.CONCAT($C25,",",I25) -> 0.122173047639603,8.20550904812508
B27: 9 | C27: =B27*PI()/180 -> 0.15707963 | D27: =IF(SIN(C27)>$I$3,$I$3,(IF(SIN(C27)<-$I$3,-$I$3,SIN(C27)))) -> 0.15643447 | E27: =IF(COS(C27)>$I$3,$I$3,(IF(COS(C27)<-$I$3,-$I$3,COS(C27)))) -> 0.98768834 | F27: =IF(TAN(C27)>$I$3,$I$3,(IF(TAN(C27)<-$I$3,-$I$3,TAN(C27)))) -> 0.15838444 | G27: =IF(_xlfn.COT(C27)>$I$3,$I$3,(IF(_xlfn.COT(C27)<-$I$3,-$I$3,_xlfn.COT(C27)))) -> 6.3137515 | H27: =IF(_xlfn.SEC(C27)>$I$3,$I$3,(IF(_xlfn.SEC(C27)<-$I$3,-$I$3,_xlfn.SEC(C27)))) -> 1.0124651 | I27: =IF(_xlfn.CSC(C27)>$I$3,$I$3,(IF(_xlfn.CSC(C27)<-$I$3,-$I$3,_xlfn.CSC(C27)))) -> 6.3924532 | K27: =_xlfn.CONCAT($C26,",",D26) -> 0.139626340159546,0.139173100960065 | L27: =_xlfn.CONCAT($C26,",",E26) -> 0.139626340159546,0.99026806874157 | M27: =_xlfn.CONCAT($C26,",",F26) -> 0.139626340159546,0.140540834702391 | N27: =_xlfn.CONCAT($C26,",",G26) -> 0.139626340159546,7.11536972238421 | O27: =_xlfn.CONCAT($C26,",",H26) -> 0.139626340159546,1.00982757251862 | P27: =_xlfn.CONCAT($C26,",",I26) -> 0.139626340159546,7.18529653432772
B28: 10 | C28: =B28*PI()/180 -> 0.17453293 | D28: =IF(SIN(C28)>$I$3,$I$3,(IF(SIN(C28)<-$I$3,-$I$3,SIN(C28)))) -> 0.17364818 | E28: =IF(COS(C28)>$I$3,$I$3,(IF(COS(C28)<-$I$3,-$I$3,COS(C28)))) -> 0.98480775 | F28: =IF(TAN(C28)>$I$3,$I$3,(IF(TAN(C28)<-$I$3,-$I$3,TAN(C28)))) -> 0.17632698 | G28: =IF(_xlfn.COT(C28)>$I$3,$I$3,(IF(_xlfn.COT(C28)<-$I$3,-$I$3,_xlfn.COT(C28)))) -> 5.6712818 | H28: =IF(_xlfn.SEC(C28)>$I$3,$I$3,(IF(_xlfn.SEC(C28)<-$I$3,-$I$3,_xlfn.SEC(C28)))) -> 1.0154266 | I28: =IF(_xlfn.CSC(C28)>$I$3,$I$3,(IF(_xlfn.CSC(C28)<-$I$3,-$I$3,_xlfn.CSC(C28)))) -> 5.7587705 | K28: =_xlfn.CONCAT($C27,",",D27) -> 0.15707963267949,0.156434465040231 | L28: =_xlfn.CONCAT($C27,",",E27) -> 0.15707963267949,0.987688340595138 | M28: =_xlfn.CONCAT($C27,",",F27) -> 0.15707963267949,0.158384440324536 | N28: =_xlfn.CONCAT($C27,",",G27) -> 0.15707963267949,6.31375151467504 | O28: =_xlfn.CONCAT($C27,",",H27) -> 0.15707963267949,1.012465125788 | P28: =_xlfn.CONCAT($C27,",",I27) -> 0.15707963267949,6.39245322149966
B29: 11 | C29: =B29*PI()/180 -> 0.19198622 | D29: =IF(SIN(C29)>$I$3,$I$3,(IF(SIN(C29)<-$I$3,-$I$3,SIN(C29)))) -> 0.190809 | E29: =IF(COS(C29)>$I$3,$I$3,(IF(COS(C29)<-$I$3,-$I$3,COS(C29)))) -> 0.98162718 | F29: =IF(TAN(C29)>$I$3,$I$3,(IF(TAN(C29)<-$I$3,-$I$3,TAN(C29)))) -> 0.19438031 | G29: =IF(_xlfn.COT(C29)>$I$3,$I$3,(IF(_xlfn.COT(C29)<-$I$3,-$I$3,_xlfn.COT(C29)))) -> 5.144554 | H29: =IF(_xlfn.SEC(C29)>$I$3,$I$3,(IF(_xlfn.SEC(C29)<-$I$3,-$I$3,_xlfn.SEC(C29)))) -> 1.0187167 | I29: =IF(_xlfn.CSC(C29)>$I$3,$I$3,(IF(_xlfn.CSC(C29)<-$I$3,-$I$3,_xlfn.CSC(C29)))) -> 5.2408431 | K29: =_xlfn.CONCAT($C28,",",D28) -> 0.174532925199433,0.17364817766693 | L29: =_xlfn.CONCAT($C28,",",E28) -> 0.174532925199433,0.984807753012208 | M29: =_xlfn.CONCAT($C28,",",F28) -> 0.174532925199433,0.176326980708465 | N29: =_xlfn.CONCAT($C28,",",G28) -> 0.174532925199433,5.67128181961771 | O29: =_xlfn.CONCAT($C28,",",H28) -> 0.174532925199433,1.01542661188575 | P29: =_xlfn.CONCAT($C28,",",I28) -> 0.174532925199433,5.75877048314363
B30: 12 | C30: =B30*PI()/180 -> 0.20943951 | D30: =IF(SIN(C30)>$I$3,$I$3,(IF(SIN(C30)<-$I$3,-$I$3,SIN(C30)))) -> 0.20791169 | E30: =IF(COS(C30)>$I$3,$I$3,(IF(COS(C30)<-$I$3,-$I$3,COS(C30)))) -> 0.9781476 | F30: =IF(TAN(C30)>$I$3,$I$3,(IF(TAN(C30)<-$I$3,-$I$3,TAN(C30)))) -> 0.21255656 | G30: =IF(_xlfn.COT(C30)>$I$3,$I$3,(IF(_xlfn.COT(C30)<-$I$3,-$I$3,_xlfn.COT(C30)))) -> 4.7046301 | H30: =IF(_xlfn.SEC(C30)>$I$3,$I$3,(IF(_xlfn.SEC(C30)<-$I$3,-$I$3,_xlfn.SEC(C30)))) -> 1.0223406 | I30: =IF(_xlfn.CSC(C30)>$I$3,$I$3,(IF(_xlfn.CSC(C30)<-$I$3,-$I$3,_xlfn.CSC(C30)))) -> 4.8097343 | K30: =_xlfn.CONCAT($C29,",",D29) -> 0.191986217719376,0.190808995376545 | L30: =_xlfn.CONCAT($C29,",",E29) -> 0.191986217719376,0.981627183447664 | M30: =_xlfn.CONCAT($C29,",",F29) -> 0.191986217719376,0.194380309137718 | N30: =_xlfn.CONCAT($C29,",",G29) -> 0.191986217719376,5.14455401597031 | O30: =_xlfn.CONCAT($C29,",",H29) -> 0.191986217719376,1.01871669495521 | P30: =_xlfn.CONCAT($C29,",",I29) -> 0.191986217719376,5.24084306416785
B31: 13 | C31: =B31*PI()/180 -> 0.2268928 | D31: =IF(SIN(C31)>$I$3,$I$3,(IF(SIN(C31)<-$I$3,-$I$3,SIN(C31)))) -> 0.22495105 | E31: =IF(COS(C31)>$I$3,$I$3,(IF(COS(C31)<-$I$3,-$I$3,COS(C31)))) -> 0.97437006 | F31: =IF(TAN(C31)>$I$3,$I$3,(IF(TAN(C31)<-$I$3,-$I$3,TAN(C31)))) -> 0.23086819 | G31: =IF(_xlfn.COT(C31)>$I$3,$I$3,(IF(_xlfn.COT(C31)<-$I$3,-$I$3,_xlfn.COT(C31)))) -> 4.3314759 | H31: =IF(_xlfn.SEC(C31)>$I$3,$I$3,(IF(_xlfn.SEC(C31)<-$I$3,-$I$3,_xlfn.SEC(C31)))) -> 1.0263041 | I31: =IF(_xlfn.CSC(C31)>$I$3,$I$3,(IF(_xlfn.CSC(C31)<-$I$3,-$I$3,_xlfn.CSC(C31)))) -> 4.4454115 | K31: =_xlfn.CONCAT($C30,",",D30) -> 0.20943951023932,0.207911690817759 | L31: =_xlfn.CONCAT($C30,",",E30) -> 0.20943951023932,0.978147600733806 | M31: =_xlfn.CONCAT($C30,",",F30) -> 0.20943951023932,0.212556561670022 | N31: =_xlfn.CONCAT($C30,",",G30) -> 0.20943951023932,4.70463010947845 | O31: =_xlfn.CONCAT($C30,",",H30) -> 0.20943951023932,1.02234059486503 | P31: =_xlfn.CONCAT($C30,",",I30) -> 0.20943951023932,4.80973434474413
... B378: 360 | C378: =B378*PI()/180 -> 6.2831853 | D378: =IF(SIN(C378)>$I$3,$I$3,(IF(SIN(C378)<-$I$3,-$I$3,SIN(C378)))) -> -2.4502969e-16 | E378: =IF(COS(C378)>$I$3,$I$3,(IF(COS(C378)<-$I$3,-$I$3,COS(C378)))) -> 1 | F378: =IF(TAN(C378)>$I$3,$I$3,(IF(TAN(C378)<-$I$3,-$I$3,TAN(C378)))) -> -2.4502969e-16 | G378: =IF(_xlfn.COT(C378)>$I$3,$I$3,(IF(_xlfn.COT(C378)<-$I$3,-$I$3,_xlfn.COT(C378)))) -> -11 | H378: =IF(_xlfn.SEC(C378)>$I$3,$I$3,(IF(_xlfn.SEC(C378)<-$I$3,-$I$3,_xlfn.SEC(C378)))) -> 1 | I378: =IF(_xlfn.CSC(C378)>$I$3,$I$3,(IF(_xlfn.CSC(C378)<-$I$3,-$I$3,_xlfn.CSC(C378)))) -> -11 | K378: =_xlfn.CONCAT($C377,",",D377) -> 6.26573201465964,-0.0174524064372844 | L378: =_xlfn.CONCAT($C377,",",E377) -> 6.26573201465964,0.999847695156391 | M378: =_xlfn.CONCAT($C377,",",F377) -> 6.26573201465964,-0.0174550649282185 | N378: =_xlfn.CONCAT($C377,",",G377) -> 6.26573201465964,-11 | O378: =_xlfn.CONCAT($C377,",",H377) -> 6.26573201465964,1.00015232804391 | P378: =_xlfn.CONCAT($C377,",",I377) -> 6.26573201465964,-11

Sheet PistaAtlDiscoRect
C1: v.20250701
B3: Pista atlética tipo disco rectángulo
B4: Parámetro | C4: Valor
B5: L curva 1 (m) | C5: 100
B6: L recta 1 (m) | C6: 100
B7: L total carril 1 (m) | C7: =C5*2+C6*2 -> 400
B8: Radio disco (m) | C8: =C5/PI() -> 31.830989
B9: Largo rectángulo (m) | C9: =C6 -> 100
B10: Alto rectángulo (m) | C10: =C8*2 -> 63.661977

Sheet Metadata
B2: Metadata
B3: Creado por r.cfdtools
B4: Pass: 1234
